{
 "cells": [
  {
   "cell_type": "code",
   "execution_count": 14,
   "metadata": {
    "execution": {
     "iopub.execute_input": "2022-11-26T00:19:51.120819Z",
     "iopub.status.busy": "2022-11-26T00:19:51.119485Z",
     "iopub.status.idle": "2022-11-26T00:19:51.129851Z",
     "shell.execute_reply": "2022-11-26T00:19:51.128858Z",
     "shell.execute_reply.started": "2022-11-26T00:19:51.120771Z"
    }
   },
   "outputs": [],
   "source": [
    "import time\n",
    "import torch\n",
    "import random\n",
    "import numpy as np\n",
    "import pandas as pd\n",
    "import torch.nn as nn\n",
    "import torch.optim as optim\n",
    "from tqdm.notebook import tqdm\n",
    "import matplotlib.pyplot as plt\n",
    "\n",
    "from torch.utils.data import DataLoader, Dataset\n",
    "\n",
    "from sklearn.model_selection import KFold, train_test_split\n",
    "from sklearn.linear_model import LogisticRegression\n",
    "\n",
    "from sklearn.base import clone as sklearn_clone\n",
    "\n",
    "from sklearn.metrics import (\n",
    "    accuracy_score, \n",
    "    f1_score, \n",
    "    recall_score,\n",
    "    precision_score,\n",
    "    roc_auc_score, confusion_matrix, roc_curve, classification_report\n",
    ")\n",
    "\n",
    "from sentence_transformers import SentenceTransformer\n",
    "from transformers import AutoTokenizer, AutoModel, HerbertTokenizer, BatchEncoding\n",
    "\n",
    "import gc\n",
    "\n",
    "from itertools import permutations, combinations, product\n",
    "from collections import OrderedDict\n",
    "\n",
    "from parallelbar import progress_map"
   ]
  },
  {
   "cell_type": "code",
   "execution_count": 2,
   "metadata": {
    "execution": {
     "iopub.execute_input": "2022-11-26T00:19:51.132143Z",
     "iopub.status.busy": "2022-11-26T00:19:51.131609Z",
     "iopub.status.idle": "2022-11-26T00:19:51.143366Z",
     "shell.execute_reply": "2022-11-26T00:19:51.142261Z",
     "shell.execute_reply.started": "2022-11-26T00:19:51.132105Z"
    }
   },
   "outputs": [
    {
     "data": {
      "text/plain": [
       "'cuda'"
      ]
     },
     "execution_count": 2,
     "metadata": {},
     "output_type": "execute_result"
    }
   ],
   "source": [
    "torch.manual_seed(111)\n",
    "np.random.seed(111)\n",
    "random.seed(111)\n",
    "device = torch.device(\"cuda\" if torch.cuda.is_available() else \"cpu\")\n",
    "\n",
    "if device.type == \"cuda\":\n",
    "    torch.cuda.get_device_name()\n",
    "    \n",
    "device.type"
   ]
  },
  {
   "cell_type": "markdown",
   "metadata": {},
   "source": [
    "## Get HerBERT"
   ]
  },
  {
   "cell_type": "code",
   "execution_count": 3,
   "metadata": {
    "execution": {
     "iopub.execute_input": "2022-11-26T00:19:51.147565Z",
     "iopub.status.busy": "2022-11-26T00:19:51.146651Z",
     "iopub.status.idle": "2022-11-26T00:19:57.477092Z",
     "shell.execute_reply": "2022-11-26T00:19:57.476066Z",
     "shell.execute_reply.started": "2022-11-26T00:19:51.147526Z"
    }
   },
   "outputs": [
    {
     "name": "stderr",
     "output_type": "stream",
     "text": [
      "Some weights of the model checkpoint at allegro/herbert-large-cased were not used when initializing BertModel: ['cls.predictions.transform.LayerNorm.weight', 'cls.sso.sso_relationship.bias', 'cls.predictions.decoder.weight', 'cls.predictions.bias', 'cls.predictions.decoder.bias', 'cls.predictions.transform.LayerNorm.bias', 'cls.sso.sso_relationship.weight', 'cls.predictions.transform.dense.weight', 'cls.predictions.transform.dense.bias']\n",
      "- This IS expected if you are initializing BertModel from the checkpoint of a model trained on another task or with another architecture (e.g. initializing a BertForSequenceClassification model from a BertForPreTraining model).\n",
      "- This IS NOT expected if you are initializing BertModel from the checkpoint of a model that you expect to be exactly identical (initializing a BertForSequenceClassification model from a BertForSequenceClassification model).\n"
     ]
    }
   ],
   "source": [
    "# tokenizer = AutoTokenizer.from_pretrained(\"allegro/herbert-large-cased\")\n",
    "model_herbert = AutoModel.from_pretrained(\"allegro/herbert-large-cased\")"
   ]
  },
  {
   "cell_type": "markdown",
   "metadata": {},
   "source": [
    "## Get data"
   ]
  },
  {
   "cell_type": "code",
   "execution_count": 5,
   "metadata": {
    "execution": {
     "iopub.execute_input": "2022-11-26T00:19:57.479337Z",
     "iopub.status.busy": "2022-11-26T00:19:57.478705Z",
     "iopub.status.idle": "2022-11-26T00:19:57.492204Z",
     "shell.execute_reply": "2022-11-26T00:19:57.491276Z",
     "shell.execute_reply.started": "2022-11-26T00:19:57.479296Z"
    }
   },
   "outputs": [],
   "source": [
    "df_topics = pd.read_csv('../datasets/ready2use/topics.csv', index_col=0)"
   ]
  },
  {
   "cell_type": "code",
   "execution_count": 6,
   "metadata": {
    "execution": {
     "iopub.execute_input": "2022-11-26T00:19:57.494169Z",
     "iopub.status.busy": "2022-11-26T00:19:57.493745Z",
     "iopub.status.idle": "2022-11-26T00:19:57.576870Z",
     "shell.execute_reply": "2022-11-26T00:19:57.575905Z",
     "shell.execute_reply.started": "2022-11-26T00:19:57.494130Z"
    }
   },
   "outputs": [],
   "source": [
    "df = pd.read_csv('../datasets/ready2use/fake_news_features_combined.csv', sep=';')\n",
    "\n",
    "df = df[ df['assestment'] != 'brak' ]\n",
    "\n",
    "df.loc[:, 'assestment'] = df['assestment'].replace({\n",
    "    'falsz' : 'Fałsz',\n",
    "    'zbity_zegar' : 'Fałsz',\n",
    "    'raczej_falsz' : 'Fałsz',\n",
    "    'prawda' : 'Prawda',\n",
    "    'blisko_prawdy' : 'Prawda',\n",
    "    'polprawda' : 'Manipulacja',\n",
    "    'Częściowy fałsz' : 'Manipulacja'\n",
    "})\n",
    "\n",
    "df = df[ df['assestment'] != 'Nieweryfikowalne' ]\n",
    "df = df[ df['assestment'] != 'Manipulacja' ]\n",
    "\n",
    "df['assestment'] = df['assestment'].replace({\n",
    "    'Fałsz' : 0,\n",
    "#     'Manipulacja' : 1,\n",
    "    'Prawda' : 1\n",
    "}).astype(int)\n",
    "\n",
    "df = df.copy()[['assestment', 'text_clean']][df.index.isin(df_topics.index)].reset_index(drop=True)"
   ]
  },
  {
   "cell_type": "code",
   "execution_count": 7,
   "metadata": {
    "execution": {
     "iopub.execute_input": "2022-11-26T00:19:57.578877Z",
     "iopub.status.busy": "2022-11-26T00:19:57.578438Z",
     "iopub.status.idle": "2022-11-26T00:19:59.378194Z",
     "shell.execute_reply": "2022-11-26T00:19:59.377137Z",
     "shell.execute_reply.started": "2022-11-26T00:19:57.578840Z"
    }
   },
   "outputs": [],
   "source": [
    "embeddings_table = pd.read_csv('../datasets/ready2use/embeddings_pl_herbert.csv', sep=\",\", header=None).values"
   ]
  },
  {
   "cell_type": "markdown",
   "metadata": {},
   "source": [
    "## Kfold"
   ]
  },
  {
   "cell_type": "code",
   "execution_count": 8,
   "metadata": {
    "execution": {
     "iopub.execute_input": "2022-11-26T00:19:59.380163Z",
     "iopub.status.busy": "2022-11-26T00:19:59.379753Z",
     "iopub.status.idle": "2022-11-26T00:19:59.413491Z",
     "shell.execute_reply": "2022-11-26T00:19:59.412631Z",
     "shell.execute_reply.started": "2022-11-26T00:19:59.380123Z"
    }
   },
   "outputs": [],
   "source": [
    "cv_fold = []\n",
    "cv_fold_i = []\n",
    "\n",
    "for i in df_topics['topic'].unique().reshape(10,-1):\n",
    "    train_cv = df_topics.index[ ~np.isin(df_topics[\"topic\"], [i, np.mod(i+1,10)]) ].values\n",
    "    val_cv = df_topics.index[ ~np.isin(df_topics[\"topic\"], np.mod(i+1,10)) ].values\n",
    "    test_cv = df_topics.index[ np.isin(df_topics[\"topic\"], i) ].values\n",
    "    \n",
    "    train_cv_i = df_topics.reset_index().index[ ~np.isin(df_topics[\"topic\"], [i, np.mod(i+1,10)]) ].values\n",
    "    val_cv_i = df_topics.reset_index().index[ ~np.isin(df_topics[\"topic\"], np.mod(i+1,10)) ].values\n",
    "    test_cv_i = df_topics.reset_index().index[ np.isin(df_topics[\"topic\"], i) ].values\n",
    "    \n",
    "    cv_fold.append( [train_cv, val_cv, test_cv])\n",
    "    cv_fold_i.append( [train_cv_i, val_cv_i, test_cv_i])"
   ]
  },
  {
   "cell_type": "code",
   "execution_count": 9,
   "metadata": {
    "execution": {
     "iopub.execute_input": "2022-11-26T00:19:59.415430Z",
     "iopub.status.busy": "2022-11-26T00:19:59.415043Z",
     "iopub.status.idle": "2022-11-26T00:19:59.461127Z",
     "shell.execute_reply": "2022-11-26T00:19:59.460275Z",
     "shell.execute_reply.started": "2022-11-26T00:19:59.415392Z"
    }
   },
   "outputs": [],
   "source": [
    "kf = KFold(n_splits=10, shuffle=True)\n",
    "kf.get_n_splits(df_topics)\n",
    "\n",
    "cv_Kfold = []\n",
    "cv_Kfold_i = []\n",
    "\n",
    "for train_index, test_index in kf.split(df_topics):\n",
    "    train_index, val_index = train_test_split(train_index, test_size=1/9, shuffle=True)\n",
    "    train_cv = df_topics.iloc[ train_index, : ].index.values\n",
    "    val_cv = df_topics.iloc[ val_index, : ].index.values\n",
    "    test_cv = df_topics.iloc[ test_index, : ].index.values\n",
    "\n",
    "    train_cv_i= df_topics.reset_index().iloc[ train_index, : ].index.values\n",
    "    val_cv_i = df_topics.reset_index().iloc[ val_index, : ].index.values\n",
    "    test_cv_i = df_topics.reset_index().iloc[ test_index, : ].index.values\n",
    "    \n",
    "    cv_Kfold.append( [train_cv, val_cv, test_cv])\n",
    "    cv_Kfold_i.append( [train_cv_i, val_cv_i, test_cv_i])"
   ]
  },
  {
   "cell_type": "markdown",
   "metadata": {},
   "source": [
    "## Train"
   ]
  },
  {
   "cell_type": "markdown",
   "metadata": {},
   "source": [
    "## TripletLoss"
   ]
  },
  {
   "cell_type": "code",
   "execution_count": 10,
   "metadata": {
    "execution": {
     "iopub.execute_input": "2022-11-26T00:19:59.465971Z",
     "iopub.status.busy": "2022-11-26T00:19:59.465695Z",
     "iopub.status.idle": "2022-11-26T00:19:59.472721Z",
     "shell.execute_reply": "2022-11-26T00:19:59.471802Z",
     "shell.execute_reply.started": "2022-11-26T00:19:59.465939Z"
    }
   },
   "outputs": [],
   "source": [
    "class TripletLoss(nn.Module):\n",
    "    def __init__(self, margin=1.0):\n",
    "        super(TripletLoss, self).__init__()\n",
    "        self.margin = margin\n",
    "        \n",
    "    def calc_euclidean(self, x1, x2):\n",
    "        return (x1 - x2).pow(2).sum(1)\n",
    "    \n",
    "    def forward(self, anchor: torch.Tensor, positive: torch.Tensor, negative: torch.Tensor) -> torch.Tensor:\n",
    "        distance_positive = self.calc_euclidean(anchor, positive)\n",
    "        distance_negative = self.calc_euclidean(anchor, negative)\n",
    "        losses = torch.relu(distance_positive - distance_negative + self.margin)\n",
    "\n",
    "        return losses.mean()"
   ]
  },
  {
   "cell_type": "markdown",
   "metadata": {},
   "source": [
    "## Define Net"
   ]
  },
  {
   "cell_type": "code",
   "execution_count": 11,
   "metadata": {
    "execution": {
     "iopub.execute_input": "2022-11-26T00:19:59.474941Z",
     "iopub.status.busy": "2022-11-26T00:19:59.474181Z",
     "iopub.status.idle": "2022-11-26T00:19:59.486174Z",
     "shell.execute_reply": "2022-11-26T00:19:59.485405Z",
     "shell.execute_reply.started": "2022-11-26T00:19:59.474904Z"
    }
   },
   "outputs": [],
   "source": [
    "class Network(nn.Module):\n",
    "    def __init__(self, emb_dim=128):\n",
    "        super(Network, self).__init__()\n",
    "        \n",
    "        self.fc = nn.Sequential(\n",
    "#             nn.Linear(1024, 1024),\n",
    "#             nn.BatchNorm1d(1024),\n",
    "#             nn.ReLU(),\n",
    "#             nn.Dropout(0.2),\n",
    "            \n",
    "            nn.Linear(1024, 512),\n",
    "            nn.BatchNorm1d(512),\n",
    "            nn.ReLU(),\n",
    "            nn.Dropout(0.5),\n",
    "            \n",
    "#             nn.Linear(512, 512),\n",
    "#             nn.BatchNorm1d(512),\n",
    "#             nn.ReLU(),\n",
    "#             nn.Dropout(0.5),\n",
    "            \n",
    "            nn.Linear(512, 256),\n",
    "            nn.BatchNorm1d(256),\n",
    "            nn.ReLU(),\n",
    "            nn.Dropout(0.5),\n",
    "            nn.Linear(256, emb_dim)\n",
    "        )\n",
    "        \n",
    "    def forward(self, x):\n",
    "        x = x.view(-1, 1024)\n",
    "        x = self.fc(x)\n",
    "        return x"
   ]
  },
  {
   "cell_type": "markdown",
   "metadata": {},
   "source": [
    "## Some testing one one kfold"
   ]
  },
  {
   "cell_type": "code",
   "execution_count": 12,
   "metadata": {
    "execution": {
     "iopub.execute_input": "2022-11-26T00:19:59.488202Z",
     "iopub.status.busy": "2022-11-26T00:19:59.487268Z",
     "iopub.status.idle": "2022-11-26T00:19:59.496850Z",
     "shell.execute_reply": "2022-11-26T00:19:59.495819Z",
     "shell.execute_reply.started": "2022-11-26T00:19:59.488165Z"
    }
   },
   "outputs": [],
   "source": [
    "embedding_dims = 128\n",
    "batch_size = 256\n",
    "epochs = 500"
   ]
  },
  {
   "cell_type": "code",
   "execution_count": 13,
   "metadata": {
    "execution": {
     "iopub.execute_input": "2022-11-26T00:19:59.498703Z",
     "iopub.status.busy": "2022-11-26T00:19:59.498171Z",
     "iopub.status.idle": "2022-11-26T00:19:59.507565Z",
     "shell.execute_reply": "2022-11-26T00:19:59.506545Z",
     "shell.execute_reply.started": "2022-11-26T00:19:59.498661Z"
    }
   },
   "outputs": [],
   "source": [
    "train_index, val_index, test_index = cv_fold_i[0]"
   ]
  },
  {
   "cell_type": "code",
   "execution_count": 15,
   "metadata": {},
   "outputs": [
    {
     "data": {
      "text/plain": [
       "16"
      ]
     },
     "execution_count": 15,
     "metadata": {},
     "output_type": "execute_result"
    }
   ],
   "source": [
    "import multiprocessing\n",
    "\n",
    "multiprocessing.cpu_count()"
   ]
  },
  {
   "cell_type": "code",
   "execution_count": 32,
   "metadata": {
    "execution": {
     "iopub.execute_input": "2022-11-26T00:19:59.509794Z",
     "iopub.status.busy": "2022-11-26T00:19:59.509319Z",
     "iopub.status.idle": "2022-11-26T00:19:59.528294Z",
     "shell.execute_reply": "2022-11-26T00:19:59.527245Z",
     "shell.execute_reply.started": "2022-11-26T00:19:59.509735Z"
    }
   },
   "outputs": [],
   "source": [
    "class FakeNews(Dataset):\n",
    "    def __init__(self, emb_dt, y_dt, index_to_use, train=False, margin=1.0):\n",
    "        self.train = train\n",
    "        self.emb = emb_dt[index_to_use]\n",
    "        self.labels = y_dt[index_to_use]\n",
    "        \n",
    "        if train:\n",
    "            indexes = np.arange(index_to_use.shape[0])\n",
    "\n",
    "            anchor_0 = list(combinations(indexes[self.labels==0], 2))\n",
    "            anchor_1 = list(combinations(indexes[self.labels==1], 2))\n",
    "            \n",
    "            triplets = {}\n",
    "            triples_len = []\n",
    "            triples_keys = []\n",
    "                        \n",
    "            for a, p in tqdm(anchor_0, total=len(anchor_0), desc='Label 0'):\n",
    "                n = indexes[self.labels==1]\n",
    "                dp = np.repeat( ((self.emb[a] - self.emb[p])**2).sum(), n.shape[0], axis=0)\n",
    "                dn = ((self.emb[a] - self.emb[n])**2).sum(1)\n",
    "                \n",
    "                mask = ((dn - dp) < margin)\n",
    "                                \n",
    "                triplets[(a,p)] = n[mask]\n",
    "                triples_keys.append((a,p))\n",
    "                triples_len.append(mask.shape[0])\n",
    "                        \n",
    "            for a, p in tqdm(anchor_1, total=len(anchor_1), desc='Label 1'):\n",
    "                n = indexes[self.labels==0]\n",
    "                dp = np.repeat( ((self.emb[a] - self.emb[p])**2).sum(), n.shape[0], axis=0)\n",
    "                dn = ((self.emb[a] - self.emb[n])**2).sum(1)\n",
    "                \n",
    "                mask = ((dn - dp) < margin)\n",
    "                                \n",
    "                triplets[(a,p)] = n[mask]\n",
    "                triples_keys.append((a,p))\n",
    "                triples_len.append(mask.shape[0])\n",
    "                    \n",
    "            self.triplets = triplets\n",
    "            self.triples_keys = triples_keys\n",
    "            self.triples_len = np.cumsum(triples_len)\n",
    "        else:\n",
    "            self.indexes = np.arange(index_to_use.shape[0])\n",
    "        \n",
    "    def __len__(self):\n",
    "        if self.train:\n",
    "            return len(self.triplets_len[-1])\n",
    "        else:\n",
    "            return len(self.emb)\n",
    "    \n",
    "    def __getitem__(self, item):\n",
    "        if self.train:\n",
    "            if item < self.triplets_len[0]:\n",
    "                a, p = self.triples_keys[0]\n",
    "                n = self.triples[self.triples_keys[0]][item]\n",
    "            else:\n",
    "                idx = [i for i,p in enumerate(self.triples_len) if p > item][0]\n",
    "                a, p = self.triples_keys[self.triples_keys[idx+1]]\n",
    "                n = self.triples_keys[self.triples_keys[idx+1]][item-self.triples_len[idx]]\n",
    "                \n",
    "#             a, p, n = self.triplets[item] \n",
    "            anchor_label = self.labels[a]\n",
    "\n",
    "            positive_item = self.emb(p)\n",
    "            negative_item = self.emb(n)\n",
    "\n",
    "            anchor_claim = self.emb[a].astype(np.float32)\n",
    "            positive_claim = self.emb[p].astype(np.float32)\n",
    "            negative_claim = self.emb[e].astype(np.float32)\n",
    "\n",
    "            anchor_label = anchor_label.astype(np.float32)\n",
    "            \n",
    "            return anchor_claim, positive_claim, negative_claim, anchor_label\n",
    "        else:\n",
    "            anchor_label = self.labels[item]\n",
    "            anchor_label = anchor_label.astype(np.float32)\n",
    "            \n",
    "            anchor_claim = self.emb[item].astype(np.float32)\n",
    "            \n",
    "            return anchor_claim, 0, 0, anchor_label"
   ]
  },
  {
   "cell_type": "code",
   "execution_count": null,
   "metadata": {
    "execution": {
     "iopub.execute_input": "2022-11-26T00:21:55.328179Z",
     "iopub.status.busy": "2022-11-26T00:21:55.327792Z",
     "iopub.status.idle": "2022-11-26T05:02:38.102384Z"
    }
   },
   "outputs": [
    {
     "data": {
      "application/vnd.jupyter.widget-view+json": {
       "model_id": "ac8ea7d9805e4566a334d98dfd6162ee",
       "version_major": 2,
       "version_minor": 0
      },
      "text/plain": [
       "Label 0:   0%|          | 0/3796390 [00:00<?, ?it/s]"
      ]
     },
     "metadata": {},
     "output_type": "display_data"
    },
    {
     "name": "stdout",
     "output_type": "stream",
     "text": [
      "Traceback (most recent call last):\n",
      "  File \"/opt/conda/lib/python3.7/site-packages/IPython/core/interactiveshell.py\", line 3552, in run_code\n",
      "    exec(code_obj, self.user_global_ns, self.user_ns)\n",
      "  File \"/tmp/ipykernel_3451/4019323611.py\", line 1, in <module>\n",
      "    train_ds = FakeNews(embeddings_table, df['assestment'].values, train_index, True)\n",
      "  File \"/tmp/ipykernel_3451/3054994583.py\", line 20, in __init__\n",
      "    dn = ((self.emb[a] - self.emb[n])**2).sum(1)\n",
      "numpy.core._exceptions._ArrayMemoryError: Unable to allocate 19.6 MiB for an array with shape (2514, 1024) and data type float64\n",
      "\n",
      "During handling of the above exception, another exception occurred:\n",
      "\n",
      "Traceback (most recent call last):\n",
      "  File \"/opt/conda/lib/python3.7/site-packages/IPython/core/interactiveshell.py\", line 2098, in showtraceback\n",
      "    stb = value._render_traceback_()\n",
      "AttributeError: 'MemoryError' object has no attribute '_render_traceback_'\n",
      "\n",
      "During handling of the above exception, another exception occurred:\n",
      "\n",
      "Traceback (most recent call last):\n",
      "  File \"/opt/conda/lib/python3.7/site-packages/IPython/core/ultratb.py\", line 1101, in get_records\n",
      "    return _fixed_getinnerframes(etb, number_of_lines_of_context, tb_offset)\n",
      "  File \"/opt/conda/lib/python3.7/site-packages/IPython/core/ultratb.py\", line 248, in wrapped\n",
      "    return f(*args, **kwargs)\n",
      "  File \"/opt/conda/lib/python3.7/site-packages/IPython/core/ultratb.py\", line 281, in _fixed_getinnerframes\n",
      "    records = fix_frame_records_filenames(inspect.getinnerframes(etb, context))\n",
      "  File \"/opt/conda/lib/python3.7/inspect.py\", line 1502, in getinnerframes\n",
      "    frameinfo = (tb.tb_frame,) + getframeinfo(tb, context)\n",
      "  File \"/opt/conda/lib/python3.7/inspect.py\", line 1460, in getframeinfo\n",
      "    filename = getsourcefile(frame) or getfile(frame)\n",
      "  File \"/opt/conda/lib/python3.7/inspect.py\", line 696, in getsourcefile\n",
      "    if getattr(getmodule(object, filename), '__loader__', None) is not None:\n",
      "  File \"/opt/conda/lib/python3.7/inspect.py\", line 732, in getmodule\n",
      "    for modname, module in sys.modules.copy().items():\n",
      "MemoryError\n",
      "Traceback (most recent call last):\n",
      "  File \"/opt/conda/lib/python3.7/site-packages/IPython/core/interactiveshell.py\", line 3552, in run_code\n",
      "    exec(code_obj, self.user_global_ns, self.user_ns)\n",
      "  File \"/tmp/ipykernel_3451/4019323611.py\", line 1, in <module>\n",
      "    train_ds = FakeNews(embeddings_table, df['assestment'].values, train_index, True)\n",
      "  File \"/tmp/ipykernel_3451/3054994583.py\", line 20, in __init__\n",
      "    dn = ((self.emb[a] - self.emb[n])**2).sum(1)\n",
      "numpy.core._exceptions._ArrayMemoryError: Unable to allocate 19.6 MiB for an array with shape (2514, 1024) and data type float64\n",
      "\n",
      "During handling of the above exception, another exception occurred:\n",
      "\n",
      "Traceback (most recent call last):\n",
      "  File \"/opt/conda/lib/python3.7/site-packages/IPython/core/interactiveshell.py\", line 2098, in showtraceback\n",
      "    stb = value._render_traceback_()\n",
      "AttributeError: 'MemoryError' object has no attribute '_render_traceback_'\n",
      "\n",
      "During handling of the above exception, another exception occurred:\n",
      "\n",
      "Traceback (most recent call last):\n",
      "  File \"/opt/conda/lib/python3.7/site-packages/IPython/core/interactiveshell.py\", line 3472, in run_ast_nodes\n",
      "    if (await self.run_code(code, result,  async_=asy)):\n",
      "  File \"/opt/conda/lib/python3.7/site-packages/IPython/core/interactiveshell.py\", line 3569, in run_code\n",
      "    self.showtraceback(running_compiled_code=True)\n",
      "  File \"/opt/conda/lib/python3.7/site-packages/IPython/core/interactiveshell.py\", line 2101, in showtraceback\n",
      "    value, tb, tb_offset=tb_offset)\n",
      "  File \"/opt/conda/lib/python3.7/site-packages/IPython/core/ultratb.py\", line 1368, in structured_traceback\n",
      "    self, etype, value, tb, tb_offset, number_of_lines_of_context)\n",
      "  File \"/opt/conda/lib/python3.7/site-packages/IPython/core/ultratb.py\", line 1268, in structured_traceback\n",
      "    self, etype, value, tb, tb_offset, number_of_lines_of_context\n",
      "  File \"/opt/conda/lib/python3.7/site-packages/IPython/core/ultratb.py\", line 1125, in structured_traceback\n",
      "    tb_offset)\n",
      "  File \"/opt/conda/lib/python3.7/site-packages/IPython/core/ultratb.py\", line 1082, in format_exception_as_a_whole\n",
      "    last_unique, recursion_repeat = find_recursion(orig_etype, evalue, records)\n",
      "  File \"/opt/conda/lib/python3.7/site-packages/IPython/core/ultratb.py\", line 382, in find_recursion\n",
      "    return len(records), 0\n",
      "TypeError: object of type 'NoneType' has no len()\n",
      "\n",
      "During handling of the above exception, another exception occurred:\n",
      "\n",
      "Traceback (most recent call last):\n",
      "  File \"/opt/conda/lib/python3.7/site-packages/IPython/core/interactiveshell.py\", line 2098, in showtraceback\n",
      "    stb = value._render_traceback_()\n",
      "AttributeError: 'TypeError' object has no attribute '_render_traceback_'\n",
      "\n",
      "During handling of the above exception, another exception occurred:\n",
      "\n",
      "Traceback (most recent call last):\n",
      "  File \"/opt/conda/lib/python3.7/site-packages/IPython/core/ultratb.py\", line 1101, in get_records\n",
      "    return _fixed_getinnerframes(etb, number_of_lines_of_context, tb_offset)\n",
      "  File \"/opt/conda/lib/python3.7/site-packages/IPython/core/ultratb.py\", line 248, in wrapped\n",
      "    return f(*args, **kwargs)\n",
      "  File \"/opt/conda/lib/python3.7/site-packages/IPython/core/ultratb.py\", line 281, in _fixed_getinnerframes\n",
      "    records = fix_frame_records_filenames(inspect.getinnerframes(etb, context))\n",
      "  File \"/opt/conda/lib/python3.7/inspect.py\", line 1502, in getinnerframes\n",
      "    frameinfo = (tb.tb_frame,) + getframeinfo(tb, context)\n",
      "  File \"/opt/conda/lib/python3.7/inspect.py\", line 1460, in getframeinfo\n",
      "    filename = getsourcefile(frame) or getfile(frame)\n",
      "  File \"/opt/conda/lib/python3.7/inspect.py\", line 696, in getsourcefile\n",
      "    if getattr(getmodule(object, filename), '__loader__', None) is not None:\n",
      "  File \"/opt/conda/lib/python3.7/inspect.py\", line 732, in getmodule\n",
      "    for modname, module in sys.modules.copy().items():\n",
      "MemoryError\n",
      "Traceback (most recent call last):\n",
      "  File \"/opt/conda/lib/python3.7/site-packages/IPython/core/interactiveshell.py\", line 3552, in run_code\n",
      "    exec(code_obj, self.user_global_ns, self.user_ns)\n",
      "  File \"/tmp/ipykernel_3451/4019323611.py\", line 1, in <module>\n",
      "    train_ds = FakeNews(embeddings_table, df['assestment'].values, train_index, True)\n",
      "  File \"/tmp/ipykernel_3451/3054994583.py\", line 20, in __init__\n",
      "    dn = ((self.emb[a] - self.emb[n])**2).sum(1)\n",
      "numpy.core._exceptions._ArrayMemoryError: Unable to allocate 19.6 MiB for an array with shape (2514, 1024) and data type float64\n",
      "\n",
      "During handling of the above exception, another exception occurred:\n",
      "\n",
      "Traceback (most recent call last):\n",
      "  File \"/opt/conda/lib/python3.7/site-packages/IPython/core/interactiveshell.py\", line 2098, in showtraceback\n",
      "    stb = value._render_traceback_()\n",
      "AttributeError: 'MemoryError' object has no attribute '_render_traceback_'\n",
      "\n",
      "During handling of the above exception, another exception occurred:\n",
      "\n",
      "Traceback (most recent call last):\n",
      "  File \"/opt/conda/lib/python3.7/site-packages/IPython/core/interactiveshell.py\", line 3472, in run_ast_nodes\n",
      "    if (await self.run_code(code, result,  async_=asy)):\n",
      "  File \"/opt/conda/lib/python3.7/site-packages/IPython/core/interactiveshell.py\", line 3569, in run_code\n",
      "    self.showtraceback(running_compiled_code=True)\n",
      "  File \"/opt/conda/lib/python3.7/site-packages/IPython/core/interactiveshell.py\", line 2101, in showtraceback\n",
      "    value, tb, tb_offset=tb_offset)\n",
      "  File \"/opt/conda/lib/python3.7/site-packages/IPython/core/ultratb.py\", line 1368, in structured_traceback\n",
      "    self, etype, value, tb, tb_offset, number_of_lines_of_context)\n",
      "  File \"/opt/conda/lib/python3.7/site-packages/IPython/core/ultratb.py\", line 1268, in structured_traceback\n",
      "    self, etype, value, tb, tb_offset, number_of_lines_of_context\n",
      "  File \"/opt/conda/lib/python3.7/site-packages/IPython/core/ultratb.py\", line 1125, in structured_traceback\n",
      "    tb_offset)\n",
      "  File \"/opt/conda/lib/python3.7/site-packages/IPython/core/ultratb.py\", line 1082, in format_exception_as_a_whole\n",
      "    last_unique, recursion_repeat = find_recursion(orig_etype, evalue, records)\n",
      "  File \"/opt/conda/lib/python3.7/site-packages/IPython/core/ultratb.py\", line 382, in find_recursion\n",
      "    return len(records), 0\n",
      "TypeError: object of type 'NoneType' has no len()\n",
      "\n",
      "During handling of the above exception, another exception occurred:\n",
      "\n",
      "Traceback (most recent call last):\n",
      "  File \"/opt/conda/lib/python3.7/site-packages/IPython/core/interactiveshell.py\", line 2098, in showtraceback\n",
      "    stb = value._render_traceback_()\n",
      "AttributeError: 'TypeError' object has no attribute '_render_traceback_'\n",
      "\n",
      "During handling of the above exception, another exception occurred:\n",
      "\n",
      "Traceback (most recent call last):\n",
      "  File \"/opt/conda/lib/python3.7/site-packages/IPython/core/interactiveshell.py\", line 3029, in _run_cell\n",
      "    return runner(coro)\n",
      "  File \"/opt/conda/lib/python3.7/site-packages/IPython/core/async_helpers.py\", line 78, in _pseudo_sync_runner\n",
      "    coro.send(None)\n",
      "  File \"/opt/conda/lib/python3.7/site-packages/IPython/core/interactiveshell.py\", line 3257, in run_cell_async\n",
      "    interactivity=interactivity, compiler=compiler, result=result)\n",
      "  File \"/opt/conda/lib/python3.7/site-packages/IPython/core/interactiveshell.py\", line 3491, in run_ast_nodes\n",
      "    self.showtraceback()\n",
      "  File \"/opt/conda/lib/python3.7/site-packages/IPython/core/interactiveshell.py\", line 2101, in showtraceback\n",
      "    value, tb, tb_offset=tb_offset)\n",
      "  File \"/opt/conda/lib/python3.7/site-packages/IPython/core/ultratb.py\", line 1368, in structured_traceback\n",
      "    self, etype, value, tb, tb_offset, number_of_lines_of_context)\n",
      "  File \"/opt/conda/lib/python3.7/site-packages/IPython/core/ultratb.py\", line 1268, in structured_traceback\n",
      "    self, etype, value, tb, tb_offset, number_of_lines_of_context\n",
      "  File \"/opt/conda/lib/python3.7/site-packages/IPython/core/ultratb.py\", line 1143, in structured_traceback\n",
      "    chained_exceptions_tb_offset)\n",
      "  File \"/opt/conda/lib/python3.7/site-packages/IPython/core/ultratb.py\", line 1082, in format_exception_as_a_whole\n",
      "    last_unique, recursion_repeat = find_recursion(orig_etype, evalue, records)\n",
      "  File \"/opt/conda/lib/python3.7/site-packages/IPython/core/ultratb.py\", line 382, in find_recursion\n",
      "    return len(records), 0\n",
      "TypeError: object of type 'NoneType' has no len()\n",
      "\n",
      "During handling of the above exception, another exception occurred:\n",
      "\n",
      "Traceback (most recent call last):\n",
      "  File \"/opt/conda/lib/python3.7/site-packages/IPython/core/interactiveshell.py\", line 2098, in showtraceback\n",
      "    stb = value._render_traceback_()\n",
      "AttributeError: 'TypeError' object has no attribute '_render_traceback_'\n",
      "\n",
      "During handling of the above exception, another exception occurred:\n",
      "\n",
      "Traceback (most recent call last):\n",
      "  File \"/opt/conda/lib/python3.7/site-packages/IPython/core/ultratb.py\", line 1101, in get_records\n",
      "    return _fixed_getinnerframes(etb, number_of_lines_of_context, tb_offset)\n",
      "  File \"/opt/conda/lib/python3.7/site-packages/IPython/core/ultratb.py\", line 248, in wrapped\n",
      "    return f(*args, **kwargs)\n",
      "  File \"/opt/conda/lib/python3.7/site-packages/IPython/core/ultratb.py\", line 281, in _fixed_getinnerframes\n",
      "    records = fix_frame_records_filenames(inspect.getinnerframes(etb, context))\n",
      "  File \"/opt/conda/lib/python3.7/inspect.py\", line 1502, in getinnerframes\n",
      "    frameinfo = (tb.tb_frame,) + getframeinfo(tb, context)\n",
      "  File \"/opt/conda/lib/python3.7/inspect.py\", line 1460, in getframeinfo\n",
      "    filename = getsourcefile(frame) or getfile(frame)\n",
      "  File \"/opt/conda/lib/python3.7/inspect.py\", line 696, in getsourcefile\n",
      "    if getattr(getmodule(object, filename), '__loader__', None) is not None:\n",
      "  File \"/opt/conda/lib/python3.7/inspect.py\", line 732, in getmodule\n",
      "    for modname, module in sys.modules.copy().items():\n",
      "MemoryError\n"
     ]
    }
   ],
   "source": [
    "train_ds = FakeNews(embeddings_table, df['assestment'].values, train_index, True)\n",
    "train_loader = DataLoader(train_ds, batch_size=batch_size, shuffle=True, num_workers=2)\n",
    "\n",
    "val_ds = FakeNews(embeddings_table, df['assestment'].values, val_index, False)\n",
    "val_loader = DataLoader(val_ds, batch_size=batch_size, shuffle=True, num_workers=2)\n",
    "\n",
    "test_ds = FakeNews(embeddings_table, df['assestment'].values, test_index, False)\n",
    "test_loader = DataLoader(test_ds, batch_size=batch_size, shuffle=False, num_workers=2)"
   ]
  },
  {
   "cell_type": "code",
   "execution_count": null,
   "metadata": {
    "execution": {
     "iopub.execute_input": "2022-11-26T05:02:38.105056Z",
     "iopub.status.busy": "2022-11-26T05:02:38.104640Z",
     "iopub.status.idle": "2022-11-26T05:02:38.142990Z"
    }
   },
   "outputs": [
    {
     "name": "stdout",
     "output_type": "stream",
     "text": [
      "Traceback (most recent call last):\n",
      "  File \"/opt/conda/lib/python3.7/site-packages/IPython/core/interactiveshell.py\", line 3552, in run_code\n",
      "    exec(code_obj, self.user_global_ns, self.user_ns)\n",
      "  File \"/tmp/ipykernel_3451/1997547849.py\", line 4, in <module>\n",
      "    pickle.dump(train_ds,fileObj)\n",
      "NameError: name 'train_ds' is not defined\n",
      "\n",
      "During handling of the above exception, another exception occurred:\n",
      "\n",
      "Traceback (most recent call last):\n",
      "  File \"/opt/conda/lib/python3.7/site-packages/IPython/core/interactiveshell.py\", line 2098, in showtraceback\n",
      "    stb = value._render_traceback_()\n",
      "AttributeError: 'NameError' object has no attribute '_render_traceback_'\n",
      "\n",
      "During handling of the above exception, another exception occurred:\n",
      "\n",
      "Traceback (most recent call last):\n",
      "  File \"/opt/conda/lib/python3.7/site-packages/IPython/core/ultratb.py\", line 1101, in get_records\n",
      "    return _fixed_getinnerframes(etb, number_of_lines_of_context, tb_offset)\n",
      "  File \"/opt/conda/lib/python3.7/site-packages/IPython/core/ultratb.py\", line 248, in wrapped\n",
      "    return f(*args, **kwargs)\n",
      "  File \"/opt/conda/lib/python3.7/site-packages/IPython/core/ultratb.py\", line 281, in _fixed_getinnerframes\n",
      "    records = fix_frame_records_filenames(inspect.getinnerframes(etb, context))\n",
      "  File \"/opt/conda/lib/python3.7/inspect.py\", line 1502, in getinnerframes\n",
      "    frameinfo = (tb.tb_frame,) + getframeinfo(tb, context)\n",
      "  File \"/opt/conda/lib/python3.7/inspect.py\", line 1460, in getframeinfo\n",
      "    filename = getsourcefile(frame) or getfile(frame)\n",
      "  File \"/opt/conda/lib/python3.7/inspect.py\", line 696, in getsourcefile\n",
      "    if getattr(getmodule(object, filename), '__loader__', None) is not None:\n",
      "  File \"/opt/conda/lib/python3.7/inspect.py\", line 732, in getmodule\n",
      "    for modname, module in sys.modules.copy().items():\n",
      "MemoryError\n",
      "Traceback (most recent call last):\n",
      "  File \"/opt/conda/lib/python3.7/site-packages/IPython/core/interactiveshell.py\", line 3552, in run_code\n",
      "    exec(code_obj, self.user_global_ns, self.user_ns)\n",
      "  File \"/tmp/ipykernel_3451/1997547849.py\", line 4, in <module>\n",
      "    pickle.dump(train_ds,fileObj)\n",
      "NameError: name 'train_ds' is not defined\n",
      "\n",
      "During handling of the above exception, another exception occurred:\n",
      "\n",
      "Traceback (most recent call last):\n",
      "  File \"/opt/conda/lib/python3.7/site-packages/IPython/core/interactiveshell.py\", line 2098, in showtraceback\n",
      "    stb = value._render_traceback_()\n",
      "AttributeError: 'NameError' object has no attribute '_render_traceback_'\n",
      "\n",
      "During handling of the above exception, another exception occurred:\n",
      "\n",
      "Traceback (most recent call last):\n",
      "  File \"/opt/conda/lib/python3.7/site-packages/IPython/core/interactiveshell.py\", line 3472, in run_ast_nodes\n",
      "    if (await self.run_code(code, result,  async_=asy)):\n",
      "  File \"/opt/conda/lib/python3.7/site-packages/IPython/core/interactiveshell.py\", line 3569, in run_code\n",
      "    self.showtraceback(running_compiled_code=True)\n",
      "  File \"/opt/conda/lib/python3.7/site-packages/IPython/core/interactiveshell.py\", line 2101, in showtraceback\n",
      "    value, tb, tb_offset=tb_offset)\n",
      "  File \"/opt/conda/lib/python3.7/site-packages/IPython/core/ultratb.py\", line 1368, in structured_traceback\n",
      "    self, etype, value, tb, tb_offset, number_of_lines_of_context)\n",
      "  File \"/opt/conda/lib/python3.7/site-packages/IPython/core/ultratb.py\", line 1268, in structured_traceback\n",
      "    self, etype, value, tb, tb_offset, number_of_lines_of_context\n",
      "  File \"/opt/conda/lib/python3.7/site-packages/IPython/core/ultratb.py\", line 1125, in structured_traceback\n",
      "    tb_offset)\n",
      "  File \"/opt/conda/lib/python3.7/site-packages/IPython/core/ultratb.py\", line 1082, in format_exception_as_a_whole\n",
      "    last_unique, recursion_repeat = find_recursion(orig_etype, evalue, records)\n",
      "  File \"/opt/conda/lib/python3.7/site-packages/IPython/core/ultratb.py\", line 382, in find_recursion\n",
      "    return len(records), 0\n",
      "TypeError: object of type 'NoneType' has no len()\n",
      "\n",
      "During handling of the above exception, another exception occurred:\n",
      "\n",
      "Traceback (most recent call last):\n",
      "  File \"/opt/conda/lib/python3.7/site-packages/IPython/core/interactiveshell.py\", line 2098, in showtraceback\n",
      "    stb = value._render_traceback_()\n",
      "AttributeError: 'TypeError' object has no attribute '_render_traceback_'\n",
      "\n",
      "During handling of the above exception, another exception occurred:\n",
      "\n",
      "Traceback (most recent call last):\n",
      "  File \"/opt/conda/lib/python3.7/site-packages/IPython/core/ultratb.py\", line 1101, in get_records\n",
      "    return _fixed_getinnerframes(etb, number_of_lines_of_context, tb_offset)\n",
      "  File \"/opt/conda/lib/python3.7/site-packages/IPython/core/ultratb.py\", line 248, in wrapped\n",
      "    return f(*args, **kwargs)\n",
      "  File \"/opt/conda/lib/python3.7/site-packages/IPython/core/ultratb.py\", line 281, in _fixed_getinnerframes\n",
      "    records = fix_frame_records_filenames(inspect.getinnerframes(etb, context))\n",
      "  File \"/opt/conda/lib/python3.7/inspect.py\", line 1502, in getinnerframes\n",
      "    frameinfo = (tb.tb_frame,) + getframeinfo(tb, context)\n",
      "  File \"/opt/conda/lib/python3.7/inspect.py\", line 1460, in getframeinfo\n",
      "    filename = getsourcefile(frame) or getfile(frame)\n",
      "  File \"/opt/conda/lib/python3.7/inspect.py\", line 696, in getsourcefile\n",
      "    if getattr(getmodule(object, filename), '__loader__', None) is not None:\n",
      "  File \"/opt/conda/lib/python3.7/inspect.py\", line 732, in getmodule\n",
      "    for modname, module in sys.modules.copy().items():\n",
      "MemoryError\n",
      "ERROR! Session/line number was not unique in database. History logging moved to new session 4\n",
      "Traceback (most recent call last):\n",
      "  File \"/opt/conda/lib/python3.7/site-packages/IPython/core/interactiveshell.py\", line 3552, in run_code\n",
      "    exec(code_obj, self.user_global_ns, self.user_ns)\n",
      "  File \"/tmp/ipykernel_3451/1997547849.py\", line 4, in <module>\n",
      "    pickle.dump(train_ds,fileObj)\n",
      "NameError: name 'train_ds' is not defined\n",
      "\n",
      "During handling of the above exception, another exception occurred:\n",
      "\n",
      "Traceback (most recent call last):\n",
      "  File \"/opt/conda/lib/python3.7/site-packages/IPython/core/interactiveshell.py\", line 2098, in showtraceback\n",
      "    stb = value._render_traceback_()\n",
      "AttributeError: 'NameError' object has no attribute '_render_traceback_'\n",
      "\n",
      "During handling of the above exception, another exception occurred:\n",
      "\n",
      "Traceback (most recent call last):\n",
      "  File \"/opt/conda/lib/python3.7/site-packages/IPython/core/interactiveshell.py\", line 3472, in run_ast_nodes\n",
      "    if (await self.run_code(code, result,  async_=asy)):\n",
      "  File \"/opt/conda/lib/python3.7/site-packages/IPython/core/interactiveshell.py\", line 3569, in run_code\n",
      "    self.showtraceback(running_compiled_code=True)\n",
      "  File \"/opt/conda/lib/python3.7/site-packages/IPython/core/interactiveshell.py\", line 2101, in showtraceback\n",
      "    value, tb, tb_offset=tb_offset)\n",
      "  File \"/opt/conda/lib/python3.7/site-packages/IPython/core/ultratb.py\", line 1368, in structured_traceback\n",
      "    self, etype, value, tb, tb_offset, number_of_lines_of_context)\n",
      "  File \"/opt/conda/lib/python3.7/site-packages/IPython/core/ultratb.py\", line 1268, in structured_traceback\n",
      "    self, etype, value, tb, tb_offset, number_of_lines_of_context\n",
      "  File \"/opt/conda/lib/python3.7/site-packages/IPython/core/ultratb.py\", line 1125, in structured_traceback\n",
      "    tb_offset)\n",
      "  File \"/opt/conda/lib/python3.7/site-packages/IPython/core/ultratb.py\", line 1082, in format_exception_as_a_whole\n",
      "    last_unique, recursion_repeat = find_recursion(orig_etype, evalue, records)\n",
      "  File \"/opt/conda/lib/python3.7/site-packages/IPython/core/ultratb.py\", line 382, in find_recursion\n",
      "    return len(records), 0\n",
      "TypeError: object of type 'NoneType' has no len()\n",
      "\n",
      "During handling of the above exception, another exception occurred:\n",
      "\n",
      "Traceback (most recent call last):\n",
      "  File \"/opt/conda/lib/python3.7/site-packages/IPython/core/interactiveshell.py\", line 2098, in showtraceback\n",
      "    stb = value._render_traceback_()\n",
      "AttributeError: 'TypeError' object has no attribute '_render_traceback_'\n",
      "\n",
      "During handling of the above exception, another exception occurred:\n",
      "\n",
      "Traceback (most recent call last):\n",
      "  File \"/opt/conda/lib/python3.7/site-packages/IPython/core/interactiveshell.py\", line 3029, in _run_cell\n",
      "    return runner(coro)\n",
      "  File \"/opt/conda/lib/python3.7/site-packages/IPython/core/async_helpers.py\", line 78, in _pseudo_sync_runner\n",
      "    coro.send(None)\n",
      "  File \"/opt/conda/lib/python3.7/site-packages/IPython/core/interactiveshell.py\", line 3257, in run_cell_async\n",
      "    interactivity=interactivity, compiler=compiler, result=result)\n",
      "  File \"/opt/conda/lib/python3.7/site-packages/IPython/core/interactiveshell.py\", line 3491, in run_ast_nodes\n",
      "    self.showtraceback()\n",
      "  File \"/opt/conda/lib/python3.7/site-packages/IPython/core/interactiveshell.py\", line 2101, in showtraceback\n",
      "    value, tb, tb_offset=tb_offset)\n",
      "  File \"/opt/conda/lib/python3.7/site-packages/IPython/core/ultratb.py\", line 1368, in structured_traceback\n",
      "    self, etype, value, tb, tb_offset, number_of_lines_of_context)\n",
      "  File \"/opt/conda/lib/python3.7/site-packages/IPython/core/ultratb.py\", line 1268, in structured_traceback\n",
      "    self, etype, value, tb, tb_offset, number_of_lines_of_context\n",
      "  File \"/opt/conda/lib/python3.7/site-packages/IPython/core/ultratb.py\", line 1143, in structured_traceback\n",
      "    chained_exceptions_tb_offset)\n",
      "  File \"/opt/conda/lib/python3.7/site-packages/IPython/core/ultratb.py\", line 1082, in format_exception_as_a_whole\n",
      "    last_unique, recursion_repeat = find_recursion(orig_etype, evalue, records)\n",
      "  File \"/opt/conda/lib/python3.7/site-packages/IPython/core/ultratb.py\", line 382, in find_recursion\n",
      "    return len(records), 0\n",
      "TypeError: object of type 'NoneType' has no len()\n",
      "\n",
      "During handling of the above exception, another exception occurred:\n",
      "\n",
      "Traceback (most recent call last):\n",
      "  File \"/opt/conda/lib/python3.7/site-packages/IPython/core/interactiveshell.py\", line 2098, in showtraceback\n",
      "    stb = value._render_traceback_()\n",
      "AttributeError: 'TypeError' object has no attribute '_render_traceback_'\n",
      "\n",
      "During handling of the above exception, another exception occurred:\n",
      "\n",
      "Traceback (most recent call last):\n",
      "  File \"/opt/conda/lib/python3.7/site-packages/IPython/core/ultratb.py\", line 1101, in get_records\n",
      "    return _fixed_getinnerframes(etb, number_of_lines_of_context, tb_offset)\n",
      "  File \"/opt/conda/lib/python3.7/site-packages/IPython/core/ultratb.py\", line 248, in wrapped\n",
      "    return f(*args, **kwargs)\n",
      "  File \"/opt/conda/lib/python3.7/site-packages/IPython/core/ultratb.py\", line 281, in _fixed_getinnerframes\n",
      "    records = fix_frame_records_filenames(inspect.getinnerframes(etb, context))\n",
      "  File \"/opt/conda/lib/python3.7/inspect.py\", line 1502, in getinnerframes\n",
      "    frameinfo = (tb.tb_frame,) + getframeinfo(tb, context)\n",
      "  File \"/opt/conda/lib/python3.7/inspect.py\", line 1460, in getframeinfo\n",
      "    filename = getsourcefile(frame) or getfile(frame)\n",
      "  File \"/opt/conda/lib/python3.7/inspect.py\", line 696, in getsourcefile\n",
      "    if getattr(getmodule(object, filename), '__loader__', None) is not None:\n",
      "  File \"/opt/conda/lib/python3.7/inspect.py\", line 732, in getmodule\n",
      "    for modname, module in sys.modules.copy().items():\n",
      "MemoryError\n"
     ]
    }
   ],
   "source": [
    "import pickle\n",
    "\n",
    "fileObj = open('train_ds.obj', 'wb')\n",
    "pickle.dump(train_ds,fileObj)\n",
    "fileObj.close()"
   ]
  },
  {
   "cell_type": "code",
   "execution_count": null,
   "metadata": {
    "execution": {
     "iopub.execute_input": "2022-11-26T05:02:38.144879Z",
     "iopub.status.busy": "2022-11-26T05:02:38.144257Z",
     "iopub.status.idle": "2022-11-26T05:02:38.208608Z"
    }
   },
   "outputs": [
    {
     "name": "stdout",
     "output_type": "stream",
     "text": [
      "ERROR! Session/line number was not unique in database. History logging moved to new session 5\n",
      "Traceback (most recent call last):\n",
      "  File \"/opt/conda/lib/python3.7/site-packages/IPython/core/interactiveshell.py\", line 3552, in run_code\n",
      "    exec(code_obj, self.user_global_ns, self.user_ns)\n",
      "  File \"/tmp/ipykernel_3451/3052651239.py\", line 1, in <module>\n",
      "    model = Network(embedding_dims)\n",
      "  File \"/tmp/ipykernel_3451/1977962058.py\", line 11, in __init__\n",
      "    nn.Linear(1024, 512),\n",
      "  File \"/opt/conda/lib/python3.7/site-packages/torch/nn/modules/linear.py\", line 85, in __init__\n",
      "    self.weight = Parameter(torch.empty((out_features, in_features), **factory_kwargs))\n",
      "RuntimeError: [enforce fail at alloc_cpu.cpp:66] . DefaultCPUAllocator: can't allocate memory: you tried to allocate 2097152 bytes. Error code 12 (Cannot allocate memory)\n",
      "\n",
      "During handling of the above exception, another exception occurred:\n",
      "\n",
      "Traceback (most recent call last):\n",
      "  File \"/opt/conda/lib/python3.7/site-packages/IPython/core/interactiveshell.py\", line 2098, in showtraceback\n",
      "    stb = value._render_traceback_()\n",
      "AttributeError: 'RuntimeError' object has no attribute '_render_traceback_'\n",
      "\n",
      "During handling of the above exception, another exception occurred:\n",
      "\n",
      "Traceback (most recent call last):\n",
      "  File \"/opt/conda/lib/python3.7/site-packages/IPython/core/ultratb.py\", line 1101, in get_records\n",
      "    return _fixed_getinnerframes(etb, number_of_lines_of_context, tb_offset)\n",
      "  File \"/opt/conda/lib/python3.7/site-packages/IPython/core/ultratb.py\", line 248, in wrapped\n",
      "    return f(*args, **kwargs)\n",
      "  File \"/opt/conda/lib/python3.7/site-packages/IPython/core/ultratb.py\", line 281, in _fixed_getinnerframes\n",
      "    records = fix_frame_records_filenames(inspect.getinnerframes(etb, context))\n",
      "  File \"/opt/conda/lib/python3.7/inspect.py\", line 1502, in getinnerframes\n",
      "    frameinfo = (tb.tb_frame,) + getframeinfo(tb, context)\n",
      "  File \"/opt/conda/lib/python3.7/inspect.py\", line 1460, in getframeinfo\n",
      "    filename = getsourcefile(frame) or getfile(frame)\n",
      "  File \"/opt/conda/lib/python3.7/inspect.py\", line 696, in getsourcefile\n",
      "    if getattr(getmodule(object, filename), '__loader__', None) is not None:\n",
      "  File \"/opt/conda/lib/python3.7/inspect.py\", line 732, in getmodule\n",
      "    for modname, module in sys.modules.copy().items():\n",
      "MemoryError\n",
      "Traceback (most recent call last):\n",
      "  File \"/opt/conda/lib/python3.7/site-packages/IPython/core/interactiveshell.py\", line 3552, in run_code\n",
      "    exec(code_obj, self.user_global_ns, self.user_ns)\n",
      "  File \"/tmp/ipykernel_3451/3052651239.py\", line 1, in <module>\n",
      "    model = Network(embedding_dims)\n",
      "  File \"/tmp/ipykernel_3451/1977962058.py\", line 11, in __init__\n",
      "    nn.Linear(1024, 512),\n",
      "  File \"/opt/conda/lib/python3.7/site-packages/torch/nn/modules/linear.py\", line 85, in __init__\n",
      "    self.weight = Parameter(torch.empty((out_features, in_features), **factory_kwargs))\n",
      "RuntimeError: [enforce fail at alloc_cpu.cpp:66] . DefaultCPUAllocator: can't allocate memory: you tried to allocate 2097152 bytes. Error code 12 (Cannot allocate memory)\n",
      "\n",
      "During handling of the above exception, another exception occurred:\n",
      "\n",
      "Traceback (most recent call last):\n",
      "  File \"/opt/conda/lib/python3.7/site-packages/IPython/core/interactiveshell.py\", line 2098, in showtraceback\n",
      "    stb = value._render_traceback_()\n",
      "AttributeError: 'RuntimeError' object has no attribute '_render_traceback_'\n",
      "\n",
      "During handling of the above exception, another exception occurred:\n",
      "\n",
      "Traceback (most recent call last):\n",
      "  File \"/opt/conda/lib/python3.7/site-packages/IPython/core/interactiveshell.py\", line 3472, in run_ast_nodes\n",
      "    if (await self.run_code(code, result,  async_=asy)):\n",
      "  File \"/opt/conda/lib/python3.7/site-packages/IPython/core/interactiveshell.py\", line 3569, in run_code\n",
      "    self.showtraceback(running_compiled_code=True)\n",
      "  File \"/opt/conda/lib/python3.7/site-packages/IPython/core/interactiveshell.py\", line 2101, in showtraceback\n",
      "    value, tb, tb_offset=tb_offset)\n",
      "  File \"/opt/conda/lib/python3.7/site-packages/IPython/core/ultratb.py\", line 1368, in structured_traceback\n",
      "    self, etype, value, tb, tb_offset, number_of_lines_of_context)\n",
      "  File \"/opt/conda/lib/python3.7/site-packages/IPython/core/ultratb.py\", line 1268, in structured_traceback\n",
      "    self, etype, value, tb, tb_offset, number_of_lines_of_context\n",
      "  File \"/opt/conda/lib/python3.7/site-packages/IPython/core/ultratb.py\", line 1125, in structured_traceback\n",
      "    tb_offset)\n",
      "  File \"/opt/conda/lib/python3.7/site-packages/IPython/core/ultratb.py\", line 1082, in format_exception_as_a_whole\n",
      "    last_unique, recursion_repeat = find_recursion(orig_etype, evalue, records)\n",
      "  File \"/opt/conda/lib/python3.7/site-packages/IPython/core/ultratb.py\", line 382, in find_recursion\n",
      "    return len(records), 0\n",
      "TypeError: object of type 'NoneType' has no len()\n",
      "\n",
      "During handling of the above exception, another exception occurred:\n",
      "\n",
      "Traceback (most recent call last):\n",
      "  File \"/opt/conda/lib/python3.7/site-packages/IPython/core/interactiveshell.py\", line 2098, in showtraceback\n",
      "    stb = value._render_traceback_()\n",
      "AttributeError: 'TypeError' object has no attribute '_render_traceback_'\n",
      "\n",
      "During handling of the above exception, another exception occurred:\n",
      "\n",
      "Traceback (most recent call last):\n",
      "  File \"/opt/conda/lib/python3.7/site-packages/IPython/core/ultratb.py\", line 1101, in get_records\n",
      "    return _fixed_getinnerframes(etb, number_of_lines_of_context, tb_offset)\n",
      "  File \"/opt/conda/lib/python3.7/site-packages/IPython/core/ultratb.py\", line 248, in wrapped\n",
      "    return f(*args, **kwargs)\n",
      "  File \"/opt/conda/lib/python3.7/site-packages/IPython/core/ultratb.py\", line 281, in _fixed_getinnerframes\n",
      "    records = fix_frame_records_filenames(inspect.getinnerframes(etb, context))\n",
      "  File \"/opt/conda/lib/python3.7/inspect.py\", line 1502, in getinnerframes\n",
      "    frameinfo = (tb.tb_frame,) + getframeinfo(tb, context)\n",
      "  File \"/opt/conda/lib/python3.7/inspect.py\", line 1460, in getframeinfo\n",
      "    filename = getsourcefile(frame) or getfile(frame)\n",
      "  File \"/opt/conda/lib/python3.7/inspect.py\", line 696, in getsourcefile\n",
      "    if getattr(getmodule(object, filename), '__loader__', None) is not None:\n",
      "  File \"/opt/conda/lib/python3.7/inspect.py\", line 732, in getmodule\n",
      "    for modname, module in sys.modules.copy().items():\n",
      "MemoryError\n",
      "Traceback (most recent call last):\n",
      "  File \"/opt/conda/lib/python3.7/site-packages/IPython/core/interactiveshell.py\", line 3552, in run_code\n",
      "    exec(code_obj, self.user_global_ns, self.user_ns)\n",
      "  File \"/tmp/ipykernel_3451/3052651239.py\", line 1, in <module>\n",
      "    model = Network(embedding_dims)\n",
      "  File \"/tmp/ipykernel_3451/1977962058.py\", line 11, in __init__\n",
      "    nn.Linear(1024, 512),\n",
      "  File \"/opt/conda/lib/python3.7/site-packages/torch/nn/modules/linear.py\", line 85, in __init__\n",
      "    self.weight = Parameter(torch.empty((out_features, in_features), **factory_kwargs))\n",
      "RuntimeError: [enforce fail at alloc_cpu.cpp:66] . DefaultCPUAllocator: can't allocate memory: you tried to allocate 2097152 bytes. Error code 12 (Cannot allocate memory)\n",
      "\n",
      "During handling of the above exception, another exception occurred:\n",
      "\n",
      "Traceback (most recent call last):\n",
      "  File \"/opt/conda/lib/python3.7/site-packages/IPython/core/interactiveshell.py\", line 2098, in showtraceback\n",
      "    stb = value._render_traceback_()\n",
      "AttributeError: 'RuntimeError' object has no attribute '_render_traceback_'\n",
      "\n",
      "During handling of the above exception, another exception occurred:\n",
      "\n",
      "Traceback (most recent call last):\n",
      "  File \"/opt/conda/lib/python3.7/site-packages/IPython/core/interactiveshell.py\", line 3472, in run_ast_nodes\n",
      "    if (await self.run_code(code, result,  async_=asy)):\n",
      "  File \"/opt/conda/lib/python3.7/site-packages/IPython/core/interactiveshell.py\", line 3569, in run_code\n",
      "    self.showtraceback(running_compiled_code=True)\n",
      "  File \"/opt/conda/lib/python3.7/site-packages/IPython/core/interactiveshell.py\", line 2101, in showtraceback\n",
      "    value, tb, tb_offset=tb_offset)\n",
      "  File \"/opt/conda/lib/python3.7/site-packages/IPython/core/ultratb.py\", line 1368, in structured_traceback\n",
      "    self, etype, value, tb, tb_offset, number_of_lines_of_context)\n",
      "  File \"/opt/conda/lib/python3.7/site-packages/IPython/core/ultratb.py\", line 1268, in structured_traceback\n",
      "    self, etype, value, tb, tb_offset, number_of_lines_of_context\n",
      "  File \"/opt/conda/lib/python3.7/site-packages/IPython/core/ultratb.py\", line 1125, in structured_traceback\n",
      "    tb_offset)\n",
      "  File \"/opt/conda/lib/python3.7/site-packages/IPython/core/ultratb.py\", line 1082, in format_exception_as_a_whole\n",
      "    last_unique, recursion_repeat = find_recursion(orig_etype, evalue, records)\n",
      "  File \"/opt/conda/lib/python3.7/site-packages/IPython/core/ultratb.py\", line 382, in find_recursion\n",
      "    return len(records), 0\n",
      "TypeError: object of type 'NoneType' has no len()\n",
      "\n",
      "During handling of the above exception, another exception occurred:\n",
      "\n",
      "Traceback (most recent call last):\n",
      "  File \"/opt/conda/lib/python3.7/site-packages/IPython/core/interactiveshell.py\", line 2098, in showtraceback\n",
      "    stb = value._render_traceback_()\n",
      "AttributeError: 'TypeError' object has no attribute '_render_traceback_'\n",
      "\n",
      "During handling of the above exception, another exception occurred:\n",
      "\n",
      "Traceback (most recent call last):\n",
      "  File \"/opt/conda/lib/python3.7/site-packages/IPython/core/interactiveshell.py\", line 3029, in _run_cell\n",
      "    return runner(coro)\n",
      "  File \"/opt/conda/lib/python3.7/site-packages/IPython/core/async_helpers.py\", line 78, in _pseudo_sync_runner\n",
      "    coro.send(None)\n",
      "  File \"/opt/conda/lib/python3.7/site-packages/IPython/core/interactiveshell.py\", line 3257, in run_cell_async\n",
      "    interactivity=interactivity, compiler=compiler, result=result)\n",
      "  File \"/opt/conda/lib/python3.7/site-packages/IPython/core/interactiveshell.py\", line 3491, in run_ast_nodes\n",
      "    self.showtraceback()\n",
      "  File \"/opt/conda/lib/python3.7/site-packages/IPython/core/interactiveshell.py\", line 2101, in showtraceback\n",
      "    value, tb, tb_offset=tb_offset)\n",
      "  File \"/opt/conda/lib/python3.7/site-packages/IPython/core/ultratb.py\", line 1368, in structured_traceback\n",
      "    self, etype, value, tb, tb_offset, number_of_lines_of_context)\n",
      "  File \"/opt/conda/lib/python3.7/site-packages/IPython/core/ultratb.py\", line 1268, in structured_traceback\n",
      "    self, etype, value, tb, tb_offset, number_of_lines_of_context\n",
      "  File \"/opt/conda/lib/python3.7/site-packages/IPython/core/ultratb.py\", line 1143, in structured_traceback\n",
      "    chained_exceptions_tb_offset)\n",
      "  File \"/opt/conda/lib/python3.7/site-packages/IPython/core/ultratb.py\", line 1082, in format_exception_as_a_whole\n",
      "    last_unique, recursion_repeat = find_recursion(orig_etype, evalue, records)\n",
      "  File \"/opt/conda/lib/python3.7/site-packages/IPython/core/ultratb.py\", line 382, in find_recursion\n",
      "    return len(records), 0\n",
      "TypeError: object of type 'NoneType' has no len()\n",
      "\n",
      "During handling of the above exception, another exception occurred:\n",
      "\n",
      "Traceback (most recent call last):\n",
      "  File \"/opt/conda/lib/python3.7/site-packages/IPython/core/interactiveshell.py\", line 2098, in showtraceback\n",
      "    stb = value._render_traceback_()\n",
      "AttributeError: 'TypeError' object has no attribute '_render_traceback_'\n",
      "\n",
      "During handling of the above exception, another exception occurred:\n",
      "\n",
      "Traceback (most recent call last):\n",
      "  File \"/opt/conda/lib/python3.7/site-packages/IPython/core/ultratb.py\", line 1101, in get_records\n",
      "    return _fixed_getinnerframes(etb, number_of_lines_of_context, tb_offset)\n",
      "  File \"/opt/conda/lib/python3.7/site-packages/IPython/core/ultratb.py\", line 248, in wrapped\n",
      "    return f(*args, **kwargs)\n",
      "  File \"/opt/conda/lib/python3.7/site-packages/IPython/core/ultratb.py\", line 281, in _fixed_getinnerframes\n",
      "    records = fix_frame_records_filenames(inspect.getinnerframes(etb, context))\n",
      "  File \"/opt/conda/lib/python3.7/inspect.py\", line 1502, in getinnerframes\n",
      "    frameinfo = (tb.tb_frame,) + getframeinfo(tb, context)\n",
      "  File \"/opt/conda/lib/python3.7/inspect.py\", line 1460, in getframeinfo\n",
      "    filename = getsourcefile(frame) or getfile(frame)\n",
      "  File \"/opt/conda/lib/python3.7/inspect.py\", line 696, in getsourcefile\n",
      "    if getattr(getmodule(object, filename), '__loader__', None) is not None:\n",
      "  File \"/opt/conda/lib/python3.7/inspect.py\", line 732, in getmodule\n",
      "    for modname, module in sys.modules.copy().items():\n",
      "MemoryError\n"
     ]
    }
   ],
   "source": [
    "model = Network(embedding_dims)\n",
    "# model = torch.nn.DataParallel(model)\n",
    "# model = torch.jit.script(model).to(device)\n",
    "model = model.to(device)\n",
    "\n",
    "optimizer = optim.Adam(model.parameters(), lr=0.001)\n",
    "# criterion = torch.jit.script(TripletLoss())\n",
    "criterion = TripletLoss()"
   ]
  },
  {
   "cell_type": "markdown",
   "metadata": {},
   "source": [
    "## Training loop"
   ]
  },
  {
   "cell_type": "code",
   "execution_count": null,
   "metadata": {
    "execution": {
     "iopub.execute_input": "2022-11-26T05:02:38.210668Z",
     "iopub.status.busy": "2022-11-26T05:02:38.210091Z",
     "iopub.status.idle": "2022-11-26T05:02:38.253488Z"
    }
   },
   "outputs": [
    {
     "name": "stdout",
     "output_type": "stream",
     "text": [
      "Traceback (most recent call last):\n",
      "  File \"/opt/conda/lib/python3.7/site-packages/IPython/core/interactiveshell.py\", line 3552, in run_code\n",
      "    exec(code_obj, self.user_global_ns, self.user_ns)\n",
      "  File \"/tmp/ipykernel_3451/466562923.py\", line 6, in <module>\n",
      "    model.train()\n",
      "NameError: name 'model' is not defined\n",
      "\n",
      "During handling of the above exception, another exception occurred:\n",
      "\n",
      "Traceback (most recent call last):\n",
      "  File \"/opt/conda/lib/python3.7/site-packages/IPython/core/interactiveshell.py\", line 2098, in showtraceback\n",
      "    stb = value._render_traceback_()\n",
      "AttributeError: 'NameError' object has no attribute '_render_traceback_'\n",
      "\n",
      "During handling of the above exception, another exception occurred:\n",
      "\n",
      "Traceback (most recent call last):\n",
      "  File \"/opt/conda/lib/python3.7/site-packages/IPython/core/ultratb.py\", line 1101, in get_records\n",
      "    return _fixed_getinnerframes(etb, number_of_lines_of_context, tb_offset)\n",
      "  File \"/opt/conda/lib/python3.7/site-packages/IPython/core/ultratb.py\", line 248, in wrapped\n",
      "    return f(*args, **kwargs)\n",
      "  File \"/opt/conda/lib/python3.7/site-packages/IPython/core/ultratb.py\", line 281, in _fixed_getinnerframes\n",
      "    records = fix_frame_records_filenames(inspect.getinnerframes(etb, context))\n",
      "  File \"/opt/conda/lib/python3.7/inspect.py\", line 1502, in getinnerframes\n",
      "    frameinfo = (tb.tb_frame,) + getframeinfo(tb, context)\n",
      "  File \"/opt/conda/lib/python3.7/inspect.py\", line 1460, in getframeinfo\n",
      "    filename = getsourcefile(frame) or getfile(frame)\n",
      "  File \"/opt/conda/lib/python3.7/inspect.py\", line 696, in getsourcefile\n",
      "    if getattr(getmodule(object, filename), '__loader__', None) is not None:\n",
      "  File \"/opt/conda/lib/python3.7/inspect.py\", line 732, in getmodule\n",
      "    for modname, module in sys.modules.copy().items():\n",
      "MemoryError\n",
      "Traceback (most recent call last):\n",
      "  File \"/opt/conda/lib/python3.7/site-packages/IPython/core/interactiveshell.py\", line 3552, in run_code\n",
      "    exec(code_obj, self.user_global_ns, self.user_ns)\n",
      "  File \"/tmp/ipykernel_3451/466562923.py\", line 6, in <module>\n",
      "    model.train()\n",
      "NameError: name 'model' is not defined\n",
      "\n",
      "During handling of the above exception, another exception occurred:\n",
      "\n",
      "Traceback (most recent call last):\n",
      "  File \"/opt/conda/lib/python3.7/site-packages/IPython/core/interactiveshell.py\", line 2098, in showtraceback\n",
      "    stb = value._render_traceback_()\n",
      "AttributeError: 'NameError' object has no attribute '_render_traceback_'\n",
      "\n",
      "During handling of the above exception, another exception occurred:\n",
      "\n",
      "Traceback (most recent call last):\n",
      "  File \"/opt/conda/lib/python3.7/site-packages/IPython/core/interactiveshell.py\", line 3472, in run_ast_nodes\n",
      "    if (await self.run_code(code, result,  async_=asy)):\n",
      "  File \"/opt/conda/lib/python3.7/site-packages/IPython/core/interactiveshell.py\", line 3569, in run_code\n",
      "    self.showtraceback(running_compiled_code=True)\n",
      "  File \"/opt/conda/lib/python3.7/site-packages/IPython/core/interactiveshell.py\", line 2101, in showtraceback\n",
      "    value, tb, tb_offset=tb_offset)\n",
      "  File \"/opt/conda/lib/python3.7/site-packages/IPython/core/ultratb.py\", line 1368, in structured_traceback\n",
      "    self, etype, value, tb, tb_offset, number_of_lines_of_context)\n",
      "  File \"/opt/conda/lib/python3.7/site-packages/IPython/core/ultratb.py\", line 1268, in structured_traceback\n",
      "    self, etype, value, tb, tb_offset, number_of_lines_of_context\n",
      "  File \"/opt/conda/lib/python3.7/site-packages/IPython/core/ultratb.py\", line 1125, in structured_traceback\n",
      "    tb_offset)\n",
      "  File \"/opt/conda/lib/python3.7/site-packages/IPython/core/ultratb.py\", line 1082, in format_exception_as_a_whole\n",
      "    last_unique, recursion_repeat = find_recursion(orig_etype, evalue, records)\n",
      "  File \"/opt/conda/lib/python3.7/site-packages/IPython/core/ultratb.py\", line 382, in find_recursion\n",
      "    return len(records), 0\n",
      "TypeError: object of type 'NoneType' has no len()\n",
      "\n",
      "During handling of the above exception, another exception occurred:\n",
      "\n",
      "Traceback (most recent call last):\n",
      "  File \"/opt/conda/lib/python3.7/site-packages/IPython/core/interactiveshell.py\", line 2098, in showtraceback\n",
      "    stb = value._render_traceback_()\n",
      "AttributeError: 'TypeError' object has no attribute '_render_traceback_'\n",
      "\n",
      "During handling of the above exception, another exception occurred:\n",
      "\n",
      "Traceback (most recent call last):\n",
      "  File \"/opt/conda/lib/python3.7/site-packages/IPython/core/ultratb.py\", line 1101, in get_records\n",
      "    return _fixed_getinnerframes(etb, number_of_lines_of_context, tb_offset)\n",
      "  File \"/opt/conda/lib/python3.7/site-packages/IPython/core/ultratb.py\", line 248, in wrapped\n",
      "    return f(*args, **kwargs)\n",
      "  File \"/opt/conda/lib/python3.7/site-packages/IPython/core/ultratb.py\", line 281, in _fixed_getinnerframes\n",
      "    records = fix_frame_records_filenames(inspect.getinnerframes(etb, context))\n",
      "  File \"/opt/conda/lib/python3.7/inspect.py\", line 1502, in getinnerframes\n",
      "    frameinfo = (tb.tb_frame,) + getframeinfo(tb, context)\n",
      "  File \"/opt/conda/lib/python3.7/inspect.py\", line 1460, in getframeinfo\n",
      "    filename = getsourcefile(frame) or getfile(frame)\n",
      "  File \"/opt/conda/lib/python3.7/inspect.py\", line 696, in getsourcefile\n",
      "    if getattr(getmodule(object, filename), '__loader__', None) is not None:\n",
      "  File \"/opt/conda/lib/python3.7/inspect.py\", line 732, in getmodule\n",
      "    for modname, module in sys.modules.copy().items():\n",
      "MemoryError\n",
      "ERROR! Session/line number was not unique in database. History logging moved to new session 6\n",
      "Traceback (most recent call last):\n",
      "  File \"/opt/conda/lib/python3.7/site-packages/IPython/core/interactiveshell.py\", line 3552, in run_code\n",
      "    exec(code_obj, self.user_global_ns, self.user_ns)\n",
      "  File \"/tmp/ipykernel_3451/466562923.py\", line 6, in <module>\n",
      "    model.train()\n",
      "NameError: name 'model' is not defined\n",
      "\n",
      "During handling of the above exception, another exception occurred:\n",
      "\n",
      "Traceback (most recent call last):\n",
      "  File \"/opt/conda/lib/python3.7/site-packages/IPython/core/interactiveshell.py\", line 2098, in showtraceback\n",
      "    stb = value._render_traceback_()\n",
      "AttributeError: 'NameError' object has no attribute '_render_traceback_'\n",
      "\n",
      "During handling of the above exception, another exception occurred:\n",
      "\n",
      "Traceback (most recent call last):\n",
      "  File \"/opt/conda/lib/python3.7/site-packages/IPython/core/interactiveshell.py\", line 3472, in run_ast_nodes\n",
      "    if (await self.run_code(code, result,  async_=asy)):\n",
      "  File \"/opt/conda/lib/python3.7/site-packages/IPython/core/interactiveshell.py\", line 3569, in run_code\n",
      "    self.showtraceback(running_compiled_code=True)\n",
      "  File \"/opt/conda/lib/python3.7/site-packages/IPython/core/interactiveshell.py\", line 2101, in showtraceback\n",
      "    value, tb, tb_offset=tb_offset)\n",
      "  File \"/opt/conda/lib/python3.7/site-packages/IPython/core/ultratb.py\", line 1368, in structured_traceback\n",
      "    self, etype, value, tb, tb_offset, number_of_lines_of_context)\n",
      "  File \"/opt/conda/lib/python3.7/site-packages/IPython/core/ultratb.py\", line 1268, in structured_traceback\n",
      "    self, etype, value, tb, tb_offset, number_of_lines_of_context\n",
      "  File \"/opt/conda/lib/python3.7/site-packages/IPython/core/ultratb.py\", line 1125, in structured_traceback\n",
      "    tb_offset)\n",
      "  File \"/opt/conda/lib/python3.7/site-packages/IPython/core/ultratb.py\", line 1082, in format_exception_as_a_whole\n",
      "    last_unique, recursion_repeat = find_recursion(orig_etype, evalue, records)\n",
      "  File \"/opt/conda/lib/python3.7/site-packages/IPython/core/ultratb.py\", line 382, in find_recursion\n",
      "    return len(records), 0\n",
      "TypeError: object of type 'NoneType' has no len()\n",
      "\n",
      "During handling of the above exception, another exception occurred:\n",
      "\n",
      "Traceback (most recent call last):\n",
      "  File \"/opt/conda/lib/python3.7/site-packages/IPython/core/interactiveshell.py\", line 2098, in showtraceback\n",
      "    stb = value._render_traceback_()\n",
      "AttributeError: 'TypeError' object has no attribute '_render_traceback_'\n",
      "\n",
      "During handling of the above exception, another exception occurred:\n",
      "\n",
      "Traceback (most recent call last):\n",
      "  File \"/opt/conda/lib/python3.7/site-packages/IPython/core/interactiveshell.py\", line 3029, in _run_cell\n",
      "    return runner(coro)\n",
      "  File \"/opt/conda/lib/python3.7/site-packages/IPython/core/async_helpers.py\", line 78, in _pseudo_sync_runner\n",
      "    coro.send(None)\n",
      "  File \"/opt/conda/lib/python3.7/site-packages/IPython/core/interactiveshell.py\", line 3257, in run_cell_async\n",
      "    interactivity=interactivity, compiler=compiler, result=result)\n",
      "  File \"/opt/conda/lib/python3.7/site-packages/IPython/core/interactiveshell.py\", line 3491, in run_ast_nodes\n",
      "    self.showtraceback()\n",
      "  File \"/opt/conda/lib/python3.7/site-packages/IPython/core/interactiveshell.py\", line 2101, in showtraceback\n",
      "    value, tb, tb_offset=tb_offset)\n",
      "  File \"/opt/conda/lib/python3.7/site-packages/IPython/core/ultratb.py\", line 1368, in structured_traceback\n",
      "    self, etype, value, tb, tb_offset, number_of_lines_of_context)\n",
      "  File \"/opt/conda/lib/python3.7/site-packages/IPython/core/ultratb.py\", line 1268, in structured_traceback\n",
      "    self, etype, value, tb, tb_offset, number_of_lines_of_context\n",
      "  File \"/opt/conda/lib/python3.7/site-packages/IPython/core/ultratb.py\", line 1143, in structured_traceback\n",
      "    chained_exceptions_tb_offset)\n",
      "  File \"/opt/conda/lib/python3.7/site-packages/IPython/core/ultratb.py\", line 1082, in format_exception_as_a_whole\n",
      "    last_unique, recursion_repeat = find_recursion(orig_etype, evalue, records)\n",
      "  File \"/opt/conda/lib/python3.7/site-packages/IPython/core/ultratb.py\", line 382, in find_recursion\n",
      "    return len(records), 0\n",
      "TypeError: object of type 'NoneType' has no len()\n",
      "\n",
      "During handling of the above exception, another exception occurred:\n",
      "\n",
      "Traceback (most recent call last):\n",
      "  File \"/opt/conda/lib/python3.7/site-packages/IPython/core/interactiveshell.py\", line 2098, in showtraceback\n",
      "    stb = value._render_traceback_()\n",
      "AttributeError: 'TypeError' object has no attribute '_render_traceback_'\n",
      "\n",
      "During handling of the above exception, another exception occurred:\n",
      "\n",
      "Traceback (most recent call last):\n",
      "  File \"/opt/conda/lib/python3.7/site-packages/IPython/core/ultratb.py\", line 1101, in get_records\n",
      "    return _fixed_getinnerframes(etb, number_of_lines_of_context, tb_offset)\n",
      "  File \"/opt/conda/lib/python3.7/site-packages/IPython/core/ultratb.py\", line 248, in wrapped\n",
      "    return f(*args, **kwargs)\n",
      "  File \"/opt/conda/lib/python3.7/site-packages/IPython/core/ultratb.py\", line 281, in _fixed_getinnerframes\n",
      "    records = fix_frame_records_filenames(inspect.getinnerframes(etb, context))\n",
      "  File \"/opt/conda/lib/python3.7/inspect.py\", line 1502, in getinnerframes\n",
      "    frameinfo = (tb.tb_frame,) + getframeinfo(tb, context)\n",
      "  File \"/opt/conda/lib/python3.7/inspect.py\", line 1460, in getframeinfo\n",
      "    filename = getsourcefile(frame) or getfile(frame)\n",
      "  File \"/opt/conda/lib/python3.7/inspect.py\", line 696, in getsourcefile\n",
      "    if getattr(getmodule(object, filename), '__loader__', None) is not None:\n",
      "  File \"/opt/conda/lib/python3.7/inspect.py\", line 732, in getmodule\n",
      "    for modname, module in sys.modules.copy().items():\n",
      "MemoryError\n"
     ]
    }
   ],
   "source": [
    "train_loss_out = []\n",
    "val_loss_out = []\n",
    "\n",
    "val_prev = np.inf\n",
    "\n",
    "model.train()\n",
    "for epoch in tqdm(range(epochs), desc=\"Epochs\"):\n",
    "    running_loss = []\n",
    "    for step, (anchor_claim, positive_claim, negative_claim, anchor_label) in enumerate(train_loader):\n",
    "        anchor_claim = (anchor_claim / torch.norm(anchor_claim) ).to(device)\n",
    "        positive_claim = (positive_claim / torch.norm(positive_claim) ).to(device)\n",
    "        negative_claim = (negative_claim / torch.norm(negative_claim) ).to(device)\n",
    "\n",
    "        optimizer.zero_grad()\n",
    "        anchor_out = model(anchor_claim)\n",
    "        positive_out = model(positive_claim)\n",
    "        negative_out = model(negative_claim)\n",
    "        \n",
    "        loss = criterion(anchor_out, positive_out, negative_out)\n",
    "        loss.backward()\n",
    "        optimizer.step()\n",
    "        \n",
    "        running_loss.append(loss.cpu().detach().numpy())\n",
    "        \n",
    "    \n",
    "    model.eval()\n",
    "    \n",
    "    val_loss = []\n",
    "    for anchor_claim, positive_claim, negative_claim, _ in val_loader:\n",
    "        anchor_claim = (anchor_claim / torch.norm(anchor_claim) ).to(device)\n",
    "        positive_claim = (positive_claim / torch.norm(positive_claim) ).to(device)\n",
    "        negative_claim = (negative_claim / torch.norm(negative_claim) ).to(device)\n",
    "\n",
    "        anchor_out = model(anchor_claim)\n",
    "        positive_out = model(positive_claim)\n",
    "        negative_out = model(negative_claim)\n",
    "        \n",
    "        loss = criterion(anchor_out, positive_out, negative_out)\n",
    "        val_loss.append(loss.cpu().detach().numpy())\n",
    "    \n",
    "    model.train()\n",
    "    \n",
    "    train_loss_out.append(np.mean(running_loss))\n",
    "    val_loss_out.append(np.mean(val_loss))\n",
    "    \n",
    "    if np.mean(val_loss) < val_prev:\n",
    "        print(epoch, f'saved {np.mean(val_loss):.4f} < {val_prev:.4f}')\n",
    "        val_prev = np.mean(val_loss)\n",
    "        torch.save(model, 'model_0_001.pt')\n",
    "        \n",
    "    if epoch%10 == 0:\n",
    "        print(f\"{j} Epoch: {epoch+1}/{epochs} - Train Loss: {np.mean(running_loss):.4f};\",\n",
    "              f\" Val Loss: {np.mean(val_loss):.4f}\")\n"
   ]
  },
  {
   "cell_type": "code",
   "execution_count": null,
   "metadata": {
    "execution": {
     "iopub.execute_input": "2022-11-26T05:02:38.255694Z",
     "iopub.status.busy": "2022-11-26T05:02:38.255083Z",
     "iopub.status.idle": "2022-11-26T05:02:38.297171Z"
    }
   },
   "outputs": [
    {
     "name": "stdout",
     "output_type": "stream",
     "text": [
      "Traceback (most recent call last):\n",
      "  File \"/opt/conda/lib/python3.7/site-packages/IPython/core/interactiveshell.py\", line 3552, in run_code\n",
      "    exec(code_obj, self.user_global_ns, self.user_ns)\n",
      "  File \"/tmp/ipykernel_3451/1100836330.py\", line 4, in <module>\n",
      "    model.eval()\n",
      "NameError: name 'model' is not defined\n",
      "\n",
      "During handling of the above exception, another exception occurred:\n",
      "\n",
      "Traceback (most recent call last):\n",
      "  File \"/opt/conda/lib/python3.7/site-packages/IPython/core/interactiveshell.py\", line 2098, in showtraceback\n",
      "    stb = value._render_traceback_()\n",
      "AttributeError: 'NameError' object has no attribute '_render_traceback_'\n",
      "\n",
      "During handling of the above exception, another exception occurred:\n",
      "\n",
      "Traceback (most recent call last):\n",
      "  File \"/opt/conda/lib/python3.7/site-packages/IPython/core/ultratb.py\", line 1101, in get_records\n",
      "    return _fixed_getinnerframes(etb, number_of_lines_of_context, tb_offset)\n",
      "  File \"/opt/conda/lib/python3.7/site-packages/IPython/core/ultratb.py\", line 248, in wrapped\n",
      "    return f(*args, **kwargs)\n",
      "  File \"/opt/conda/lib/python3.7/site-packages/IPython/core/ultratb.py\", line 281, in _fixed_getinnerframes\n",
      "    records = fix_frame_records_filenames(inspect.getinnerframes(etb, context))\n",
      "  File \"/opt/conda/lib/python3.7/inspect.py\", line 1502, in getinnerframes\n",
      "    frameinfo = (tb.tb_frame,) + getframeinfo(tb, context)\n",
      "  File \"/opt/conda/lib/python3.7/inspect.py\", line 1460, in getframeinfo\n",
      "    filename = getsourcefile(frame) or getfile(frame)\n",
      "  File \"/opt/conda/lib/python3.7/inspect.py\", line 696, in getsourcefile\n",
      "    if getattr(getmodule(object, filename), '__loader__', None) is not None:\n",
      "  File \"/opt/conda/lib/python3.7/inspect.py\", line 732, in getmodule\n",
      "    for modname, module in sys.modules.copy().items():\n",
      "MemoryError\n",
      "Traceback (most recent call last):\n",
      "  File \"/opt/conda/lib/python3.7/site-packages/IPython/core/interactiveshell.py\", line 3552, in run_code\n",
      "    exec(code_obj, self.user_global_ns, self.user_ns)\n",
      "  File \"/tmp/ipykernel_3451/1100836330.py\", line 4, in <module>\n",
      "    model.eval()\n",
      "NameError: name 'model' is not defined\n",
      "\n",
      "During handling of the above exception, another exception occurred:\n",
      "\n",
      "Traceback (most recent call last):\n",
      "  File \"/opt/conda/lib/python3.7/site-packages/IPython/core/interactiveshell.py\", line 2098, in showtraceback\n",
      "    stb = value._render_traceback_()\n",
      "AttributeError: 'NameError' object has no attribute '_render_traceback_'\n",
      "\n",
      "During handling of the above exception, another exception occurred:\n",
      "\n",
      "Traceback (most recent call last):\n",
      "  File \"/opt/conda/lib/python3.7/site-packages/IPython/core/interactiveshell.py\", line 3472, in run_ast_nodes\n",
      "    if (await self.run_code(code, result,  async_=asy)):\n",
      "  File \"/opt/conda/lib/python3.7/site-packages/IPython/core/interactiveshell.py\", line 3569, in run_code\n",
      "    self.showtraceback(running_compiled_code=True)\n",
      "  File \"/opt/conda/lib/python3.7/site-packages/IPython/core/interactiveshell.py\", line 2101, in showtraceback\n",
      "    value, tb, tb_offset=tb_offset)\n",
      "  File \"/opt/conda/lib/python3.7/site-packages/IPython/core/ultratb.py\", line 1368, in structured_traceback\n",
      "    self, etype, value, tb, tb_offset, number_of_lines_of_context)\n",
      "  File \"/opt/conda/lib/python3.7/site-packages/IPython/core/ultratb.py\", line 1268, in structured_traceback\n",
      "    self, etype, value, tb, tb_offset, number_of_lines_of_context\n",
      "  File \"/opt/conda/lib/python3.7/site-packages/IPython/core/ultratb.py\", line 1125, in structured_traceback\n",
      "    tb_offset)\n",
      "  File \"/opt/conda/lib/python3.7/site-packages/IPython/core/ultratb.py\", line 1082, in format_exception_as_a_whole\n",
      "    last_unique, recursion_repeat = find_recursion(orig_etype, evalue, records)\n",
      "  File \"/opt/conda/lib/python3.7/site-packages/IPython/core/ultratb.py\", line 382, in find_recursion\n",
      "    return len(records), 0\n",
      "TypeError: object of type 'NoneType' has no len()\n",
      "\n",
      "During handling of the above exception, another exception occurred:\n",
      "\n",
      "Traceback (most recent call last):\n",
      "  File \"/opt/conda/lib/python3.7/site-packages/IPython/core/interactiveshell.py\", line 2098, in showtraceback\n",
      "    stb = value._render_traceback_()\n",
      "AttributeError: 'TypeError' object has no attribute '_render_traceback_'\n",
      "\n",
      "During handling of the above exception, another exception occurred:\n",
      "\n",
      "Traceback (most recent call last):\n",
      "  File \"/opt/conda/lib/python3.7/site-packages/IPython/core/ultratb.py\", line 1101, in get_records\n",
      "    return _fixed_getinnerframes(etb, number_of_lines_of_context, tb_offset)\n",
      "  File \"/opt/conda/lib/python3.7/site-packages/IPython/core/ultratb.py\", line 248, in wrapped\n",
      "    return f(*args, **kwargs)\n",
      "  File \"/opt/conda/lib/python3.7/site-packages/IPython/core/ultratb.py\", line 281, in _fixed_getinnerframes\n",
      "    records = fix_frame_records_filenames(inspect.getinnerframes(etb, context))\n",
      "  File \"/opt/conda/lib/python3.7/inspect.py\", line 1502, in getinnerframes\n",
      "    frameinfo = (tb.tb_frame,) + getframeinfo(tb, context)\n",
      "  File \"/opt/conda/lib/python3.7/inspect.py\", line 1460, in getframeinfo\n",
      "    filename = getsourcefile(frame) or getfile(frame)\n",
      "  File \"/opt/conda/lib/python3.7/inspect.py\", line 696, in getsourcefile\n",
      "    if getattr(getmodule(object, filename), '__loader__', None) is not None:\n",
      "  File \"/opt/conda/lib/python3.7/inspect.py\", line 732, in getmodule\n",
      "    for modname, module in sys.modules.copy().items():\n",
      "MemoryError\n",
      "ERROR! Session/line number was not unique in database. History logging moved to new session 7\n",
      "Traceback (most recent call last):\n",
      "  File \"/opt/conda/lib/python3.7/site-packages/IPython/core/interactiveshell.py\", line 3552, in run_code\n",
      "    exec(code_obj, self.user_global_ns, self.user_ns)\n",
      "  File \"/tmp/ipykernel_3451/1100836330.py\", line 4, in <module>\n",
      "    model.eval()\n",
      "NameError: name 'model' is not defined\n",
      "\n",
      "During handling of the above exception, another exception occurred:\n",
      "\n",
      "Traceback (most recent call last):\n",
      "  File \"/opt/conda/lib/python3.7/site-packages/IPython/core/interactiveshell.py\", line 2098, in showtraceback\n",
      "    stb = value._render_traceback_()\n",
      "AttributeError: 'NameError' object has no attribute '_render_traceback_'\n",
      "\n",
      "During handling of the above exception, another exception occurred:\n",
      "\n",
      "Traceback (most recent call last):\n",
      "  File \"/opt/conda/lib/python3.7/site-packages/IPython/core/interactiveshell.py\", line 3472, in run_ast_nodes\n",
      "    if (await self.run_code(code, result,  async_=asy)):\n",
      "  File \"/opt/conda/lib/python3.7/site-packages/IPython/core/interactiveshell.py\", line 3569, in run_code\n",
      "    self.showtraceback(running_compiled_code=True)\n",
      "  File \"/opt/conda/lib/python3.7/site-packages/IPython/core/interactiveshell.py\", line 2101, in showtraceback\n",
      "    value, tb, tb_offset=tb_offset)\n",
      "  File \"/opt/conda/lib/python3.7/site-packages/IPython/core/ultratb.py\", line 1368, in structured_traceback\n",
      "    self, etype, value, tb, tb_offset, number_of_lines_of_context)\n",
      "  File \"/opt/conda/lib/python3.7/site-packages/IPython/core/ultratb.py\", line 1268, in structured_traceback\n",
      "    self, etype, value, tb, tb_offset, number_of_lines_of_context\n",
      "  File \"/opt/conda/lib/python3.7/site-packages/IPython/core/ultratb.py\", line 1125, in structured_traceback\n",
      "    tb_offset)\n",
      "  File \"/opt/conda/lib/python3.7/site-packages/IPython/core/ultratb.py\", line 1082, in format_exception_as_a_whole\n",
      "    last_unique, recursion_repeat = find_recursion(orig_etype, evalue, records)\n",
      "  File \"/opt/conda/lib/python3.7/site-packages/IPython/core/ultratb.py\", line 382, in find_recursion\n",
      "    return len(records), 0\n",
      "TypeError: object of type 'NoneType' has no len()\n",
      "\n",
      "During handling of the above exception, another exception occurred:\n",
      "\n",
      "Traceback (most recent call last):\n",
      "  File \"/opt/conda/lib/python3.7/site-packages/IPython/core/interactiveshell.py\", line 2098, in showtraceback\n",
      "    stb = value._render_traceback_()\n",
      "AttributeError: 'TypeError' object has no attribute '_render_traceback_'\n",
      "\n",
      "During handling of the above exception, another exception occurred:\n",
      "\n",
      "Traceback (most recent call last):\n",
      "  File \"/opt/conda/lib/python3.7/site-packages/IPython/core/interactiveshell.py\", line 3029, in _run_cell\n",
      "    return runner(coro)\n",
      "  File \"/opt/conda/lib/python3.7/site-packages/IPython/core/async_helpers.py\", line 78, in _pseudo_sync_runner\n",
      "    coro.send(None)\n",
      "  File \"/opt/conda/lib/python3.7/site-packages/IPython/core/interactiveshell.py\", line 3257, in run_cell_async\n",
      "    interactivity=interactivity, compiler=compiler, result=result)\n",
      "  File \"/opt/conda/lib/python3.7/site-packages/IPython/core/interactiveshell.py\", line 3491, in run_ast_nodes\n",
      "    self.showtraceback()\n",
      "  File \"/opt/conda/lib/python3.7/site-packages/IPython/core/interactiveshell.py\", line 2101, in showtraceback\n",
      "    value, tb, tb_offset=tb_offset)\n",
      "  File \"/opt/conda/lib/python3.7/site-packages/IPython/core/ultratb.py\", line 1368, in structured_traceback\n",
      "    self, etype, value, tb, tb_offset, number_of_lines_of_context)\n",
      "  File \"/opt/conda/lib/python3.7/site-packages/IPython/core/ultratb.py\", line 1268, in structured_traceback\n",
      "    self, etype, value, tb, tb_offset, number_of_lines_of_context\n",
      "  File \"/opt/conda/lib/python3.7/site-packages/IPython/core/ultratb.py\", line 1143, in structured_traceback\n",
      "    chained_exceptions_tb_offset)\n",
      "  File \"/opt/conda/lib/python3.7/site-packages/IPython/core/ultratb.py\", line 1082, in format_exception_as_a_whole\n",
      "    last_unique, recursion_repeat = find_recursion(orig_etype, evalue, records)\n",
      "  File \"/opt/conda/lib/python3.7/site-packages/IPython/core/ultratb.py\", line 382, in find_recursion\n",
      "    return len(records), 0\n",
      "TypeError: object of type 'NoneType' has no len()\n",
      "\n",
      "During handling of the above exception, another exception occurred:\n",
      "\n",
      "Traceback (most recent call last):\n",
      "  File \"/opt/conda/lib/python3.7/site-packages/IPython/core/interactiveshell.py\", line 2098, in showtraceback\n",
      "    stb = value._render_traceback_()\n",
      "AttributeError: 'TypeError' object has no attribute '_render_traceback_'\n",
      "\n",
      "During handling of the above exception, another exception occurred:\n",
      "\n",
      "Traceback (most recent call last):\n",
      "  File \"/opt/conda/lib/python3.7/site-packages/IPython/core/ultratb.py\", line 1101, in get_records\n",
      "    return _fixed_getinnerframes(etb, number_of_lines_of_context, tb_offset)\n",
      "  File \"/opt/conda/lib/python3.7/site-packages/IPython/core/ultratb.py\", line 248, in wrapped\n",
      "    return f(*args, **kwargs)\n",
      "  File \"/opt/conda/lib/python3.7/site-packages/IPython/core/ultratb.py\", line 281, in _fixed_getinnerframes\n",
      "    records = fix_frame_records_filenames(inspect.getinnerframes(etb, context))\n",
      "  File \"/opt/conda/lib/python3.7/inspect.py\", line 1502, in getinnerframes\n",
      "    frameinfo = (tb.tb_frame,) + getframeinfo(tb, context)\n",
      "  File \"/opt/conda/lib/python3.7/inspect.py\", line 1460, in getframeinfo\n",
      "    filename = getsourcefile(frame) or getfile(frame)\n",
      "  File \"/opt/conda/lib/python3.7/inspect.py\", line 696, in getsourcefile\n",
      "    if getattr(getmodule(object, filename), '__loader__', None) is not None:\n",
      "  File \"/opt/conda/lib/python3.7/inspect.py\", line 732, in getmodule\n",
      "    for modname, module in sys.modules.copy().items():\n",
      "MemoryError\n"
     ]
    }
   ],
   "source": [
    "train_results = []\n",
    "labels = []\n",
    "\n",
    "model.eval()\n",
    "with torch.no_grad():\n",
    "    for claim, _, _, label in tqdm(train_loader):\n",
    "        anchor_claim = claim.to(device)\n",
    "        \n",
    "        train_results.append(model(anchor_claim).cpu().numpy())\n",
    "        labels.append(label)\n",
    "        \n",
    "#         del anchor_claim \n",
    "#         gc.collect()\n",
    "#         torch.cuda.empty_cache()\n",
    "\n",
    "train_results = np.concatenate(train_results) \n",
    "labels = np.concatenate(labels)\n",
    "train_results.shape"
   ]
  },
  {
   "cell_type": "code",
   "execution_count": 34,
   "metadata": {
    "execution": {
     "iopub.execute_input": "2022-11-26T05:02:38.299645Z",
     "iopub.status.busy": "2022-11-26T05:02:38.298924Z",
     "iopub.status.idle": "2022-11-26T05:02:38.414267Z",
     "shell.execute_reply": "2022-11-26T05:02:38.412959Z",
     "shell.execute_reply.started": "2022-11-26T05:02:38.299596Z"
    }
   },
   "outputs": [
    {
     "name": "stdout",
     "output_type": "stream",
     "text": [
      "ERROR! Session/line number was not unique in database. History logging moved to new session 8\n"
     ]
    },
    {
     "ename": "MemoryError",
     "evalue": "In RendererAgg: Out of memory",
     "output_type": "error",
     "traceback": [
      "\u001b[0;31m---------------------------------------------------------------------------\u001b[0m",
      "\u001b[0;31mMemoryError\u001b[0m                               Traceback (most recent call last)",
      "\u001b[0;32m/opt/conda/lib/python3.7/site-packages/IPython/core/formatters.py\u001b[0m in \u001b[0;36m__call__\u001b[0;34m(self, obj)\u001b[0m\n\u001b[1;32m    339\u001b[0m                 \u001b[0;32mpass\u001b[0m\u001b[0;34m\u001b[0m\u001b[0;34m\u001b[0m\u001b[0m\n\u001b[1;32m    340\u001b[0m             \u001b[0;32melse\u001b[0m\u001b[0;34m:\u001b[0m\u001b[0;34m\u001b[0m\u001b[0;34m\u001b[0m\u001b[0m\n\u001b[0;32m--> 341\u001b[0;31m                 \u001b[0;32mreturn\u001b[0m \u001b[0mprinter\u001b[0m\u001b[0;34m(\u001b[0m\u001b[0mobj\u001b[0m\u001b[0;34m)\u001b[0m\u001b[0;34m\u001b[0m\u001b[0;34m\u001b[0m\u001b[0m\n\u001b[0m\u001b[1;32m    342\u001b[0m             \u001b[0;31m# Finally look for special method names\u001b[0m\u001b[0;34m\u001b[0m\u001b[0;34m\u001b[0m\u001b[0;34m\u001b[0m\u001b[0m\n\u001b[1;32m    343\u001b[0m             \u001b[0mmethod\u001b[0m \u001b[0;34m=\u001b[0m \u001b[0mget_real_method\u001b[0m\u001b[0;34m(\u001b[0m\u001b[0mobj\u001b[0m\u001b[0;34m,\u001b[0m \u001b[0mself\u001b[0m\u001b[0;34m.\u001b[0m\u001b[0mprint_method\u001b[0m\u001b[0;34m)\u001b[0m\u001b[0;34m\u001b[0m\u001b[0;34m\u001b[0m\u001b[0m\n",
      "\u001b[0;32m/opt/conda/lib/python3.7/site-packages/IPython/core/pylabtools.py\u001b[0m in \u001b[0;36mprint_figure\u001b[0;34m(fig, fmt, bbox_inches, base64, **kwargs)\u001b[0m\n\u001b[1;32m    149\u001b[0m         \u001b[0mFigureCanvasBase\u001b[0m\u001b[0;34m(\u001b[0m\u001b[0mfig\u001b[0m\u001b[0;34m)\u001b[0m\u001b[0;34m\u001b[0m\u001b[0;34m\u001b[0m\u001b[0m\n\u001b[1;32m    150\u001b[0m \u001b[0;34m\u001b[0m\u001b[0m\n\u001b[0;32m--> 151\u001b[0;31m     \u001b[0mfig\u001b[0m\u001b[0;34m.\u001b[0m\u001b[0mcanvas\u001b[0m\u001b[0;34m.\u001b[0m\u001b[0mprint_figure\u001b[0m\u001b[0;34m(\u001b[0m\u001b[0mbytes_io\u001b[0m\u001b[0;34m,\u001b[0m \u001b[0;34m**\u001b[0m\u001b[0mkw\u001b[0m\u001b[0;34m)\u001b[0m\u001b[0;34m\u001b[0m\u001b[0;34m\u001b[0m\u001b[0m\n\u001b[0m\u001b[1;32m    152\u001b[0m     \u001b[0mdata\u001b[0m \u001b[0;34m=\u001b[0m \u001b[0mbytes_io\u001b[0m\u001b[0;34m.\u001b[0m\u001b[0mgetvalue\u001b[0m\u001b[0;34m(\u001b[0m\u001b[0;34m)\u001b[0m\u001b[0;34m\u001b[0m\u001b[0;34m\u001b[0m\u001b[0m\n\u001b[1;32m    153\u001b[0m     \u001b[0;32mif\u001b[0m \u001b[0mfmt\u001b[0m \u001b[0;34m==\u001b[0m \u001b[0;34m'svg'\u001b[0m\u001b[0;34m:\u001b[0m\u001b[0;34m\u001b[0m\u001b[0;34m\u001b[0m\u001b[0m\n",
      "\u001b[0;32m/opt/conda/lib/python3.7/site-packages/matplotlib/backend_bases.py\u001b[0m in \u001b[0;36mprint_figure\u001b[0;34m(self, filename, dpi, facecolor, edgecolor, orientation, format, bbox_inches, pad_inches, bbox_extra_artists, backend, **kwargs)\u001b[0m\n\u001b[1;32m   2290\u001b[0m                     \u001b[0mself\u001b[0m\u001b[0;34m.\u001b[0m\u001b[0mfigure\u001b[0m\u001b[0;34m,\u001b[0m\u001b[0;34m\u001b[0m\u001b[0;34m\u001b[0m\u001b[0m\n\u001b[1;32m   2291\u001b[0m                     functools.partial(\n\u001b[0;32m-> 2292\u001b[0;31m                         print_method, orientation=orientation)\n\u001b[0m\u001b[1;32m   2293\u001b[0m                 )\n\u001b[1;32m   2294\u001b[0m                 \u001b[0;32mwith\u001b[0m \u001b[0mgetattr\u001b[0m\u001b[0;34m(\u001b[0m\u001b[0mrenderer\u001b[0m\u001b[0;34m,\u001b[0m \u001b[0;34m\"_draw_disabled\"\u001b[0m\u001b[0;34m,\u001b[0m \u001b[0mnullcontext\u001b[0m\u001b[0;34m)\u001b[0m\u001b[0;34m(\u001b[0m\u001b[0;34m)\u001b[0m\u001b[0;34m:\u001b[0m\u001b[0;34m\u001b[0m\u001b[0;34m\u001b[0m\u001b[0m\n",
      "\u001b[0;32m/opt/conda/lib/python3.7/site-packages/matplotlib/backend_bases.py\u001b[0m in \u001b[0;36m_get_renderer\u001b[0;34m(figure, print_method)\u001b[0m\n\u001b[1;32m   1542\u001b[0m                 figure.canvas._get_output_canvas(None, fmt), f\"print_{fmt}\")\n\u001b[1;32m   1543\u001b[0m         \u001b[0;32mtry\u001b[0m\u001b[0;34m:\u001b[0m\u001b[0;34m\u001b[0m\u001b[0;34m\u001b[0m\u001b[0m\n\u001b[0;32m-> 1544\u001b[0;31m             \u001b[0mprint_method\u001b[0m\u001b[0;34m(\u001b[0m\u001b[0mio\u001b[0m\u001b[0;34m.\u001b[0m\u001b[0mBytesIO\u001b[0m\u001b[0;34m(\u001b[0m\u001b[0;34m)\u001b[0m\u001b[0;34m)\u001b[0m\u001b[0;34m\u001b[0m\u001b[0;34m\u001b[0m\u001b[0m\n\u001b[0m\u001b[1;32m   1545\u001b[0m         \u001b[0;32mexcept\u001b[0m \u001b[0mDone\u001b[0m \u001b[0;32mas\u001b[0m \u001b[0mexc\u001b[0m\u001b[0;34m:\u001b[0m\u001b[0;34m\u001b[0m\u001b[0;34m\u001b[0m\u001b[0m\n\u001b[1;32m   1546\u001b[0m             \u001b[0mrenderer\u001b[0m\u001b[0;34m,\u001b[0m \u001b[0;34m=\u001b[0m \u001b[0mfigure\u001b[0m\u001b[0;34m.\u001b[0m\u001b[0m_cachedRenderer\u001b[0m\u001b[0;34m,\u001b[0m \u001b[0;34m=\u001b[0m \u001b[0mexc\u001b[0m\u001b[0;34m.\u001b[0m\u001b[0margs\u001b[0m\u001b[0;34m\u001b[0m\u001b[0;34m\u001b[0m\u001b[0m\n",
      "\u001b[0;32m/opt/conda/lib/python3.7/site-packages/matplotlib/backend_bases.py\u001b[0m in \u001b[0;36mwrapper\u001b[0;34m(*args, **kwargs)\u001b[0m\n\u001b[1;32m   1646\u001b[0m             \u001b[0mkwargs\u001b[0m\u001b[0;34m.\u001b[0m\u001b[0mpop\u001b[0m\u001b[0;34m(\u001b[0m\u001b[0marg\u001b[0m\u001b[0;34m)\u001b[0m\u001b[0;34m\u001b[0m\u001b[0;34m\u001b[0m\u001b[0m\n\u001b[1;32m   1647\u001b[0m \u001b[0;34m\u001b[0m\u001b[0m\n\u001b[0;32m-> 1648\u001b[0;31m         \u001b[0;32mreturn\u001b[0m \u001b[0mfunc\u001b[0m\u001b[0;34m(\u001b[0m\u001b[0;34m*\u001b[0m\u001b[0margs\u001b[0m\u001b[0;34m,\u001b[0m \u001b[0;34m**\u001b[0m\u001b[0mkwargs\u001b[0m\u001b[0;34m)\u001b[0m\u001b[0;34m\u001b[0m\u001b[0;34m\u001b[0m\u001b[0m\n\u001b[0m\u001b[1;32m   1649\u001b[0m \u001b[0;34m\u001b[0m\u001b[0m\n\u001b[1;32m   1650\u001b[0m     \u001b[0;32mreturn\u001b[0m \u001b[0mwrapper\u001b[0m\u001b[0;34m\u001b[0m\u001b[0;34m\u001b[0m\u001b[0m\n",
      "\u001b[0;32m/opt/conda/lib/python3.7/site-packages/matplotlib/_api/deprecation.py\u001b[0m in \u001b[0;36mwrapper\u001b[0;34m(*inner_args, **inner_kwargs)\u001b[0m\n\u001b[1;32m    413\u001b[0m                          \u001b[0;32melse\u001b[0m \u001b[0mdeprecation_addendum\u001b[0m\u001b[0;34m,\u001b[0m\u001b[0;34m\u001b[0m\u001b[0;34m\u001b[0m\u001b[0m\n\u001b[1;32m    414\u001b[0m                 **kwargs)\n\u001b[0;32m--> 415\u001b[0;31m         \u001b[0;32mreturn\u001b[0m \u001b[0mfunc\u001b[0m\u001b[0;34m(\u001b[0m\u001b[0;34m*\u001b[0m\u001b[0minner_args\u001b[0m\u001b[0;34m,\u001b[0m \u001b[0;34m**\u001b[0m\u001b[0minner_kwargs\u001b[0m\u001b[0;34m)\u001b[0m\u001b[0;34m\u001b[0m\u001b[0;34m\u001b[0m\u001b[0m\n\u001b[0m\u001b[1;32m    416\u001b[0m \u001b[0;34m\u001b[0m\u001b[0m\n\u001b[1;32m    417\u001b[0m     \u001b[0mDECORATORS\u001b[0m\u001b[0;34m[\u001b[0m\u001b[0mwrapper\u001b[0m\u001b[0;34m]\u001b[0m \u001b[0;34m=\u001b[0m \u001b[0mdecorator\u001b[0m\u001b[0;34m\u001b[0m\u001b[0;34m\u001b[0m\u001b[0m\n",
      "\u001b[0;32m/opt/conda/lib/python3.7/site-packages/matplotlib/backends/backend_agg.py\u001b[0m in \u001b[0;36mprint_png\u001b[0;34m(self, filename_or_obj, metadata, pil_kwargs, *args)\u001b[0m\n\u001b[1;32m    538\u001b[0m             \u001b[0;34m*\u001b[0m\u001b[0mmetadata\u001b[0m\u001b[0;34m*\u001b[0m\u001b[0;34m,\u001b[0m \u001b[0mincluding\u001b[0m \u001b[0mthe\u001b[0m \u001b[0mdefault\u001b[0m \u001b[0;34m'Software'\u001b[0m \u001b[0mkey\u001b[0m\u001b[0;34m.\u001b[0m\u001b[0;34m\u001b[0m\u001b[0;34m\u001b[0m\u001b[0m\n\u001b[1;32m    539\u001b[0m         \"\"\"\n\u001b[0;32m--> 540\u001b[0;31m         \u001b[0mFigureCanvasAgg\u001b[0m\u001b[0;34m.\u001b[0m\u001b[0mdraw\u001b[0m\u001b[0;34m(\u001b[0m\u001b[0mself\u001b[0m\u001b[0;34m)\u001b[0m\u001b[0;34m\u001b[0m\u001b[0;34m\u001b[0m\u001b[0m\n\u001b[0m\u001b[1;32m    541\u001b[0m         mpl.image.imsave(\n\u001b[1;32m    542\u001b[0m             \u001b[0mfilename_or_obj\u001b[0m\u001b[0;34m,\u001b[0m \u001b[0mself\u001b[0m\u001b[0;34m.\u001b[0m\u001b[0mbuffer_rgba\u001b[0m\u001b[0;34m(\u001b[0m\u001b[0;34m)\u001b[0m\u001b[0;34m,\u001b[0m \u001b[0mformat\u001b[0m\u001b[0;34m=\u001b[0m\u001b[0;34m\"png\"\u001b[0m\u001b[0;34m,\u001b[0m \u001b[0morigin\u001b[0m\u001b[0;34m=\u001b[0m\u001b[0;34m\"upper\"\u001b[0m\u001b[0;34m,\u001b[0m\u001b[0;34m\u001b[0m\u001b[0;34m\u001b[0m\u001b[0m\n",
      "\u001b[0;32m/opt/conda/lib/python3.7/site-packages/matplotlib/backends/backend_agg.py\u001b[0m in \u001b[0;36mdraw\u001b[0;34m(self)\u001b[0m\n\u001b[1;32m    429\u001b[0m     \u001b[0;32mdef\u001b[0m \u001b[0mdraw\u001b[0m\u001b[0;34m(\u001b[0m\u001b[0mself\u001b[0m\u001b[0;34m)\u001b[0m\u001b[0;34m:\u001b[0m\u001b[0;34m\u001b[0m\u001b[0;34m\u001b[0m\u001b[0m\n\u001b[1;32m    430\u001b[0m         \u001b[0;31m# docstring inherited\u001b[0m\u001b[0;34m\u001b[0m\u001b[0;34m\u001b[0m\u001b[0;34m\u001b[0m\u001b[0m\n\u001b[0;32m--> 431\u001b[0;31m         \u001b[0mself\u001b[0m\u001b[0;34m.\u001b[0m\u001b[0mrenderer\u001b[0m \u001b[0;34m=\u001b[0m \u001b[0mself\u001b[0m\u001b[0;34m.\u001b[0m\u001b[0mget_renderer\u001b[0m\u001b[0;34m(\u001b[0m\u001b[0mcleared\u001b[0m\u001b[0;34m=\u001b[0m\u001b[0;32mTrue\u001b[0m\u001b[0;34m)\u001b[0m\u001b[0;34m\u001b[0m\u001b[0;34m\u001b[0m\u001b[0m\n\u001b[0m\u001b[1;32m    432\u001b[0m         \u001b[0;31m# Acquire a lock on the shared font cache.\u001b[0m\u001b[0;34m\u001b[0m\u001b[0;34m\u001b[0m\u001b[0;34m\u001b[0m\u001b[0m\n\u001b[1;32m    433\u001b[0m         \u001b[0;32mwith\u001b[0m \u001b[0mRendererAgg\u001b[0m\u001b[0;34m.\u001b[0m\u001b[0mlock\u001b[0m\u001b[0;34m,\u001b[0m\u001b[0;31m \u001b[0m\u001b[0;31m\\\u001b[0m\u001b[0;34m\u001b[0m\u001b[0;34m\u001b[0m\u001b[0m\n",
      "\u001b[0;32m/opt/conda/lib/python3.7/site-packages/matplotlib/backends/backend_agg.py\u001b[0m in \u001b[0;36mget_renderer\u001b[0;34m(self, cleared)\u001b[0m\n\u001b[1;32m    445\u001b[0m                           and getattr(self, \"_lastKey\", None) == key)\n\u001b[1;32m    446\u001b[0m         \u001b[0;32mif\u001b[0m \u001b[0;32mnot\u001b[0m \u001b[0mreuse_renderer\u001b[0m\u001b[0;34m:\u001b[0m\u001b[0;34m\u001b[0m\u001b[0;34m\u001b[0m\u001b[0m\n\u001b[0;32m--> 447\u001b[0;31m             \u001b[0mself\u001b[0m\u001b[0;34m.\u001b[0m\u001b[0mrenderer\u001b[0m \u001b[0;34m=\u001b[0m \u001b[0mRendererAgg\u001b[0m\u001b[0;34m(\u001b[0m\u001b[0mw\u001b[0m\u001b[0;34m,\u001b[0m \u001b[0mh\u001b[0m\u001b[0;34m,\u001b[0m \u001b[0mself\u001b[0m\u001b[0;34m.\u001b[0m\u001b[0mfigure\u001b[0m\u001b[0;34m.\u001b[0m\u001b[0mdpi\u001b[0m\u001b[0;34m)\u001b[0m\u001b[0;34m\u001b[0m\u001b[0;34m\u001b[0m\u001b[0m\n\u001b[0m\u001b[1;32m    448\u001b[0m             \u001b[0mself\u001b[0m\u001b[0;34m.\u001b[0m\u001b[0m_lastKey\u001b[0m \u001b[0;34m=\u001b[0m \u001b[0mkey\u001b[0m\u001b[0;34m\u001b[0m\u001b[0;34m\u001b[0m\u001b[0m\n\u001b[1;32m    449\u001b[0m         \u001b[0;32melif\u001b[0m \u001b[0mcleared\u001b[0m\u001b[0;34m:\u001b[0m\u001b[0;34m\u001b[0m\u001b[0;34m\u001b[0m\u001b[0m\n",
      "\u001b[0;32m/opt/conda/lib/python3.7/site-packages/matplotlib/backends/backend_agg.py\u001b[0m in \u001b[0;36m__init__\u001b[0;34m(self, width, height, dpi)\u001b[0m\n\u001b[1;32m     91\u001b[0m         \u001b[0mself\u001b[0m\u001b[0;34m.\u001b[0m\u001b[0mwidth\u001b[0m \u001b[0;34m=\u001b[0m \u001b[0mwidth\u001b[0m\u001b[0;34m\u001b[0m\u001b[0;34m\u001b[0m\u001b[0m\n\u001b[1;32m     92\u001b[0m         \u001b[0mself\u001b[0m\u001b[0;34m.\u001b[0m\u001b[0mheight\u001b[0m \u001b[0;34m=\u001b[0m \u001b[0mheight\u001b[0m\u001b[0;34m\u001b[0m\u001b[0;34m\u001b[0m\u001b[0m\n\u001b[0;32m---> 93\u001b[0;31m         \u001b[0mself\u001b[0m\u001b[0;34m.\u001b[0m\u001b[0m_renderer\u001b[0m \u001b[0;34m=\u001b[0m \u001b[0m_RendererAgg\u001b[0m\u001b[0;34m(\u001b[0m\u001b[0mint\u001b[0m\u001b[0;34m(\u001b[0m\u001b[0mwidth\u001b[0m\u001b[0;34m)\u001b[0m\u001b[0;34m,\u001b[0m \u001b[0mint\u001b[0m\u001b[0;34m(\u001b[0m\u001b[0mheight\u001b[0m\u001b[0;34m)\u001b[0m\u001b[0;34m,\u001b[0m \u001b[0mdpi\u001b[0m\u001b[0;34m)\u001b[0m\u001b[0;34m\u001b[0m\u001b[0;34m\u001b[0m\u001b[0m\n\u001b[0m\u001b[1;32m     94\u001b[0m         \u001b[0mself\u001b[0m\u001b[0;34m.\u001b[0m\u001b[0m_filter_renderers\u001b[0m \u001b[0;34m=\u001b[0m \u001b[0;34m[\u001b[0m\u001b[0;34m]\u001b[0m\u001b[0;34m\u001b[0m\u001b[0;34m\u001b[0m\u001b[0m\n\u001b[1;32m     95\u001b[0m \u001b[0;34m\u001b[0m\u001b[0m\n",
      "\u001b[0;31mMemoryError\u001b[0m: In RendererAgg: Out of memory"
     ]
    },
    {
     "data": {
      "text/plain": [
       "<Figure size 576x432 with 1 Axes>"
      ]
     },
     "metadata": {},
     "output_type": "display_data"
    }
   ],
   "source": [
    "plt.figure(figsize=(8, 6), facecolor=\"azure\")\n",
    "for label in np.unique(labels):\n",
    "    tmp = train_results[labels==label]\n",
    "    plt.scatter(tmp[:, 0], tmp[:, 1], label=label)\n",
    "\n",
    "plt.legend()\n",
    "plt.show()"
   ]
  },
  {
   "cell_type": "code",
   "execution_count": null,
   "metadata": {
    "execution": {
     "iopub.execute_input": "2022-11-26T05:02:38.417735Z",
     "iopub.status.busy": "2022-11-26T05:02:38.417260Z",
     "iopub.status.idle": "2022-11-26T05:02:38.488620Z"
    }
   },
   "outputs": [
    {
     "name": "stdout",
     "output_type": "stream",
     "text": [
      "Traceback (most recent call last):\n",
      "  File \"/opt/conda/lib/python3.7/site-packages/IPython/core/interactiveshell.py\", line 3552, in run_code\n",
      "    exec(code_obj, self.user_global_ns, self.user_ns)\n",
      "  File \"/tmp/ipykernel_3451/2194404495.py\", line 4, in <module>\n",
      "    model.eval()\n",
      "NameError: name 'model' is not defined\n",
      "\n",
      "During handling of the above exception, another exception occurred:\n",
      "\n",
      "Traceback (most recent call last):\n",
      "  File \"/opt/conda/lib/python3.7/site-packages/IPython/core/interactiveshell.py\", line 2098, in showtraceback\n",
      "    stb = value._render_traceback_()\n",
      "AttributeError: 'NameError' object has no attribute '_render_traceback_'\n",
      "\n",
      "During handling of the above exception, another exception occurred:\n",
      "\n",
      "Traceback (most recent call last):\n",
      "  File \"/opt/conda/lib/python3.7/site-packages/IPython/core/ultratb.py\", line 1101, in get_records\n",
      "    return _fixed_getinnerframes(etb, number_of_lines_of_context, tb_offset)\n",
      "  File \"/opt/conda/lib/python3.7/site-packages/IPython/core/ultratb.py\", line 248, in wrapped\n",
      "    return f(*args, **kwargs)\n",
      "  File \"/opt/conda/lib/python3.7/site-packages/IPython/core/ultratb.py\", line 281, in _fixed_getinnerframes\n",
      "    records = fix_frame_records_filenames(inspect.getinnerframes(etb, context))\n",
      "  File \"/opt/conda/lib/python3.7/inspect.py\", line 1502, in getinnerframes\n",
      "    frameinfo = (tb.tb_frame,) + getframeinfo(tb, context)\n",
      "  File \"/opt/conda/lib/python3.7/inspect.py\", line 1460, in getframeinfo\n",
      "    filename = getsourcefile(frame) or getfile(frame)\n",
      "  File \"/opt/conda/lib/python3.7/inspect.py\", line 696, in getsourcefile\n",
      "    if getattr(getmodule(object, filename), '__loader__', None) is not None:\n",
      "  File \"/opt/conda/lib/python3.7/inspect.py\", line 732, in getmodule\n",
      "    for modname, module in sys.modules.copy().items():\n",
      "MemoryError\n",
      "Traceback (most recent call last):\n",
      "  File \"/opt/conda/lib/python3.7/site-packages/IPython/core/interactiveshell.py\", line 3552, in run_code\n",
      "    exec(code_obj, self.user_global_ns, self.user_ns)\n",
      "  File \"/tmp/ipykernel_3451/2194404495.py\", line 4, in <module>\n",
      "    model.eval()\n",
      "NameError: name 'model' is not defined\n",
      "\n",
      "During handling of the above exception, another exception occurred:\n",
      "\n",
      "Traceback (most recent call last):\n",
      "  File \"/opt/conda/lib/python3.7/site-packages/IPython/core/interactiveshell.py\", line 2098, in showtraceback\n",
      "    stb = value._render_traceback_()\n",
      "AttributeError: 'NameError' object has no attribute '_render_traceback_'\n",
      "\n",
      "During handling of the above exception, another exception occurred:\n",
      "\n",
      "Traceback (most recent call last):\n",
      "  File \"/opt/conda/lib/python3.7/site-packages/IPython/core/interactiveshell.py\", line 3472, in run_ast_nodes\n",
      "    if (await self.run_code(code, result,  async_=asy)):\n",
      "  File \"/opt/conda/lib/python3.7/site-packages/IPython/core/interactiveshell.py\", line 3569, in run_code\n",
      "    self.showtraceback(running_compiled_code=True)\n",
      "  File \"/opt/conda/lib/python3.7/site-packages/IPython/core/interactiveshell.py\", line 2101, in showtraceback\n",
      "    value, tb, tb_offset=tb_offset)\n",
      "  File \"/opt/conda/lib/python3.7/site-packages/IPython/core/ultratb.py\", line 1368, in structured_traceback\n",
      "    self, etype, value, tb, tb_offset, number_of_lines_of_context)\n",
      "  File \"/opt/conda/lib/python3.7/site-packages/IPython/core/ultratb.py\", line 1268, in structured_traceback\n",
      "    self, etype, value, tb, tb_offset, number_of_lines_of_context\n",
      "  File \"/opt/conda/lib/python3.7/site-packages/IPython/core/ultratb.py\", line 1125, in structured_traceback\n",
      "    tb_offset)\n",
      "  File \"/opt/conda/lib/python3.7/site-packages/IPython/core/ultratb.py\", line 1082, in format_exception_as_a_whole\n",
      "    last_unique, recursion_repeat = find_recursion(orig_etype, evalue, records)\n",
      "  File \"/opt/conda/lib/python3.7/site-packages/IPython/core/ultratb.py\", line 382, in find_recursion\n",
      "    return len(records), 0\n",
      "TypeError: object of type 'NoneType' has no len()\n",
      "\n",
      "During handling of the above exception, another exception occurred:\n",
      "\n",
      "Traceback (most recent call last):\n",
      "  File \"/opt/conda/lib/python3.7/site-packages/IPython/core/interactiveshell.py\", line 2098, in showtraceback\n",
      "    stb = value._render_traceback_()\n",
      "AttributeError: 'TypeError' object has no attribute '_render_traceback_'\n",
      "\n",
      "During handling of the above exception, another exception occurred:\n",
      "\n",
      "Traceback (most recent call last):\n",
      "  File \"/opt/conda/lib/python3.7/site-packages/IPython/core/ultratb.py\", line 1101, in get_records\n",
      "    return _fixed_getinnerframes(etb, number_of_lines_of_context, tb_offset)\n",
      "  File \"/opt/conda/lib/python3.7/site-packages/IPython/core/ultratb.py\", line 248, in wrapped\n",
      "    return f(*args, **kwargs)\n",
      "  File \"/opt/conda/lib/python3.7/site-packages/IPython/core/ultratb.py\", line 281, in _fixed_getinnerframes\n",
      "    records = fix_frame_records_filenames(inspect.getinnerframes(etb, context))\n",
      "  File \"/opt/conda/lib/python3.7/inspect.py\", line 1502, in getinnerframes\n",
      "    frameinfo = (tb.tb_frame,) + getframeinfo(tb, context)\n",
      "  File \"/opt/conda/lib/python3.7/inspect.py\", line 1460, in getframeinfo\n",
      "    filename = getsourcefile(frame) or getfile(frame)\n",
      "  File \"/opt/conda/lib/python3.7/inspect.py\", line 696, in getsourcefile\n",
      "    if getattr(getmodule(object, filename), '__loader__', None) is not None:\n",
      "  File \"/opt/conda/lib/python3.7/inspect.py\", line 732, in getmodule\n",
      "    for modname, module in sys.modules.copy().items():\n",
      "MemoryError\n",
      "Traceback (most recent call last):\n",
      "  File \"/opt/conda/lib/python3.7/site-packages/IPython/core/interactiveshell.py\", line 3552, in run_code\n",
      "    exec(code_obj, self.user_global_ns, self.user_ns)\n",
      "  File \"/tmp/ipykernel_3451/2194404495.py\", line 4, in <module>\n",
      "    model.eval()\n",
      "NameError: name 'model' is not defined\n",
      "\n",
      "During handling of the above exception, another exception occurred:\n",
      "\n",
      "Traceback (most recent call last):\n",
      "  File \"/opt/conda/lib/python3.7/site-packages/IPython/core/interactiveshell.py\", line 2098, in showtraceback\n",
      "    stb = value._render_traceback_()\n",
      "AttributeError: 'NameError' object has no attribute '_render_traceback_'\n",
      "\n",
      "During handling of the above exception, another exception occurred:\n",
      "\n",
      "Traceback (most recent call last):\n",
      "  File \"/opt/conda/lib/python3.7/site-packages/IPython/core/interactiveshell.py\", line 3472, in run_ast_nodes\n",
      "    if (await self.run_code(code, result,  async_=asy)):\n",
      "  File \"/opt/conda/lib/python3.7/site-packages/IPython/core/interactiveshell.py\", line 3569, in run_code\n",
      "    self.showtraceback(running_compiled_code=True)\n",
      "  File \"/opt/conda/lib/python3.7/site-packages/IPython/core/interactiveshell.py\", line 2101, in showtraceback\n",
      "    value, tb, tb_offset=tb_offset)\n",
      "  File \"/opt/conda/lib/python3.7/site-packages/IPython/core/ultratb.py\", line 1368, in structured_traceback\n",
      "    self, etype, value, tb, tb_offset, number_of_lines_of_context)\n",
      "  File \"/opt/conda/lib/python3.7/site-packages/IPython/core/ultratb.py\", line 1268, in structured_traceback\n",
      "    self, etype, value, tb, tb_offset, number_of_lines_of_context\n",
      "  File \"/opt/conda/lib/python3.7/site-packages/IPython/core/ultratb.py\", line 1125, in structured_traceback\n",
      "    tb_offset)\n",
      "  File \"/opt/conda/lib/python3.7/site-packages/IPython/core/ultratb.py\", line 1082, in format_exception_as_a_whole\n",
      "    last_unique, recursion_repeat = find_recursion(orig_etype, evalue, records)\n",
      "  File \"/opt/conda/lib/python3.7/site-packages/IPython/core/ultratb.py\", line 382, in find_recursion\n",
      "    return len(records), 0\n",
      "TypeError: object of type 'NoneType' has no len()\n",
      "\n",
      "During handling of the above exception, another exception occurred:\n",
      "\n",
      "Traceback (most recent call last):\n",
      "  File \"/opt/conda/lib/python3.7/site-packages/IPython/core/interactiveshell.py\", line 2098, in showtraceback\n",
      "    stb = value._render_traceback_()\n",
      "AttributeError: 'TypeError' object has no attribute '_render_traceback_'\n",
      "\n",
      "During handling of the above exception, another exception occurred:\n",
      "\n",
      "Traceback (most recent call last):\n",
      "  File \"/opt/conda/lib/python3.7/site-packages/IPython/core/interactiveshell.py\", line 3029, in _run_cell\n",
      "    return runner(coro)\n",
      "  File \"/opt/conda/lib/python3.7/site-packages/IPython/core/async_helpers.py\", line 78, in _pseudo_sync_runner\n",
      "    coro.send(None)\n",
      "  File \"/opt/conda/lib/python3.7/site-packages/IPython/core/interactiveshell.py\", line 3257, in run_cell_async\n",
      "    interactivity=interactivity, compiler=compiler, result=result)\n",
      "  File \"/opt/conda/lib/python3.7/site-packages/IPython/core/interactiveshell.py\", line 3491, in run_ast_nodes\n",
      "    self.showtraceback()\n",
      "  File \"/opt/conda/lib/python3.7/site-packages/IPython/core/interactiveshell.py\", line 2101, in showtraceback\n",
      "    value, tb, tb_offset=tb_offset)\n",
      "  File \"/opt/conda/lib/python3.7/site-packages/IPython/core/ultratb.py\", line 1368, in structured_traceback\n",
      "    self, etype, value, tb, tb_offset, number_of_lines_of_context)\n",
      "  File \"/opt/conda/lib/python3.7/site-packages/IPython/core/ultratb.py\", line 1268, in structured_traceback\n",
      "    self, etype, value, tb, tb_offset, number_of_lines_of_context\n",
      "  File \"/opt/conda/lib/python3.7/site-packages/IPython/core/ultratb.py\", line 1143, in structured_traceback\n",
      "    chained_exceptions_tb_offset)\n",
      "  File \"/opt/conda/lib/python3.7/site-packages/IPython/core/ultratb.py\", line 1082, in format_exception_as_a_whole\n",
      "    last_unique, recursion_repeat = find_recursion(orig_etype, evalue, records)\n",
      "  File \"/opt/conda/lib/python3.7/site-packages/IPython/core/ultratb.py\", line 382, in find_recursion\n",
      "    return len(records), 0\n",
      "TypeError: object of type 'NoneType' has no len()\n",
      "\n",
      "During handling of the above exception, another exception occurred:\n",
      "\n",
      "Traceback (most recent call last):\n",
      "  File \"/opt/conda/lib/python3.7/site-packages/IPython/core/interactiveshell.py\", line 2098, in showtraceback\n",
      "    stb = value._render_traceback_()\n",
      "AttributeError: 'TypeError' object has no attribute '_render_traceback_'\n",
      "\n",
      "During handling of the above exception, another exception occurred:\n",
      "\n",
      "Traceback (most recent call last):\n",
      "  File \"/opt/conda/lib/python3.7/site-packages/IPython/core/ultratb.py\", line 1101, in get_records\n",
      "    return _fixed_getinnerframes(etb, number_of_lines_of_context, tb_offset)\n",
      "  File \"/opt/conda/lib/python3.7/site-packages/IPython/core/ultratb.py\", line 248, in wrapped\n",
      "    return f(*args, **kwargs)\n",
      "  File \"/opt/conda/lib/python3.7/site-packages/IPython/core/ultratb.py\", line 281, in _fixed_getinnerframes\n",
      "    records = fix_frame_records_filenames(inspect.getinnerframes(etb, context))\n",
      "  File \"/opt/conda/lib/python3.7/inspect.py\", line 1502, in getinnerframes\n",
      "    frameinfo = (tb.tb_frame,) + getframeinfo(tb, context)\n",
      "  File \"/opt/conda/lib/python3.7/inspect.py\", line 1460, in getframeinfo\n",
      "    filename = getsourcefile(frame) or getfile(frame)\n",
      "  File \"/opt/conda/lib/python3.7/inspect.py\", line 696, in getsourcefile\n",
      "    if getattr(getmodule(object, filename), '__loader__', None) is not None:\n",
      "  File \"/opt/conda/lib/python3.7/inspect.py\", line 732, in getmodule\n",
      "    for modname, module in sys.modules.copy().items():\n",
      "MemoryError\n"
     ]
    }
   ],
   "source": [
    "test_results = []\n",
    "test_labels = []\n",
    "\n",
    "model.eval()\n",
    "with torch.no_grad():\n",
    "    for claim, _, _, label in tqdm(train_loader):\n",
    "        anchor_claim = claim.to(device)\n",
    "        \n",
    "        test_results.append(model(anchor_claim).cpu().numpy())\n",
    "        test_labels.append(label)\n",
    "        \n",
    "#         del anchor_claim \n",
    "#         gc.collect()\n",
    "#         torch.cuda.empty_cache()\n",
    "\n",
    "test_results = np.concatenate(test_results)\n",
    "test_labels = np.concatenate(test_labels)\n",
    "test_results.shape"
   ]
  },
  {
   "cell_type": "code",
   "execution_count": 35,
   "metadata": {
    "execution": {
     "iopub.execute_input": "2022-11-26T05:02:38.491591Z",
     "iopub.status.busy": "2022-11-26T05:02:38.490641Z",
     "iopub.status.idle": "2022-11-26T05:02:38.574082Z",
     "shell.execute_reply": "2022-11-26T05:02:38.572802Z",
     "shell.execute_reply.started": "2022-11-26T05:02:38.491539Z"
    }
   },
   "outputs": [
    {
     "name": "stdout",
     "output_type": "stream",
     "text": [
      "ERROR! Session/line number was not unique in database. History logging moved to new session 9\n"
     ]
    },
    {
     "ename": "MemoryError",
     "evalue": "In RendererAgg: Out of memory",
     "output_type": "error",
     "traceback": [
      "\u001b[0;31m---------------------------------------------------------------------------\u001b[0m",
      "\u001b[0;31mMemoryError\u001b[0m                               Traceback (most recent call last)",
      "\u001b[0;32m/opt/conda/lib/python3.7/site-packages/IPython/core/formatters.py\u001b[0m in \u001b[0;36m__call__\u001b[0;34m(self, obj)\u001b[0m\n\u001b[1;32m    339\u001b[0m                 \u001b[0;32mpass\u001b[0m\u001b[0;34m\u001b[0m\u001b[0;34m\u001b[0m\u001b[0m\n\u001b[1;32m    340\u001b[0m             \u001b[0;32melse\u001b[0m\u001b[0;34m:\u001b[0m\u001b[0;34m\u001b[0m\u001b[0;34m\u001b[0m\u001b[0m\n\u001b[0;32m--> 341\u001b[0;31m                 \u001b[0;32mreturn\u001b[0m \u001b[0mprinter\u001b[0m\u001b[0;34m(\u001b[0m\u001b[0mobj\u001b[0m\u001b[0;34m)\u001b[0m\u001b[0;34m\u001b[0m\u001b[0;34m\u001b[0m\u001b[0m\n\u001b[0m\u001b[1;32m    342\u001b[0m             \u001b[0;31m# Finally look for special method names\u001b[0m\u001b[0;34m\u001b[0m\u001b[0;34m\u001b[0m\u001b[0;34m\u001b[0m\u001b[0m\n\u001b[1;32m    343\u001b[0m             \u001b[0mmethod\u001b[0m \u001b[0;34m=\u001b[0m \u001b[0mget_real_method\u001b[0m\u001b[0;34m(\u001b[0m\u001b[0mobj\u001b[0m\u001b[0;34m,\u001b[0m \u001b[0mself\u001b[0m\u001b[0;34m.\u001b[0m\u001b[0mprint_method\u001b[0m\u001b[0;34m)\u001b[0m\u001b[0;34m\u001b[0m\u001b[0;34m\u001b[0m\u001b[0m\n",
      "\u001b[0;32m/opt/conda/lib/python3.7/site-packages/IPython/core/pylabtools.py\u001b[0m in \u001b[0;36mprint_figure\u001b[0;34m(fig, fmt, bbox_inches, base64, **kwargs)\u001b[0m\n\u001b[1;32m    149\u001b[0m         \u001b[0mFigureCanvasBase\u001b[0m\u001b[0;34m(\u001b[0m\u001b[0mfig\u001b[0m\u001b[0;34m)\u001b[0m\u001b[0;34m\u001b[0m\u001b[0;34m\u001b[0m\u001b[0m\n\u001b[1;32m    150\u001b[0m \u001b[0;34m\u001b[0m\u001b[0m\n\u001b[0;32m--> 151\u001b[0;31m     \u001b[0mfig\u001b[0m\u001b[0;34m.\u001b[0m\u001b[0mcanvas\u001b[0m\u001b[0;34m.\u001b[0m\u001b[0mprint_figure\u001b[0m\u001b[0;34m(\u001b[0m\u001b[0mbytes_io\u001b[0m\u001b[0;34m,\u001b[0m \u001b[0;34m**\u001b[0m\u001b[0mkw\u001b[0m\u001b[0;34m)\u001b[0m\u001b[0;34m\u001b[0m\u001b[0;34m\u001b[0m\u001b[0m\n\u001b[0m\u001b[1;32m    152\u001b[0m     \u001b[0mdata\u001b[0m \u001b[0;34m=\u001b[0m \u001b[0mbytes_io\u001b[0m\u001b[0;34m.\u001b[0m\u001b[0mgetvalue\u001b[0m\u001b[0;34m(\u001b[0m\u001b[0;34m)\u001b[0m\u001b[0;34m\u001b[0m\u001b[0;34m\u001b[0m\u001b[0m\n\u001b[1;32m    153\u001b[0m     \u001b[0;32mif\u001b[0m \u001b[0mfmt\u001b[0m \u001b[0;34m==\u001b[0m \u001b[0;34m'svg'\u001b[0m\u001b[0;34m:\u001b[0m\u001b[0;34m\u001b[0m\u001b[0;34m\u001b[0m\u001b[0m\n",
      "\u001b[0;32m/opt/conda/lib/python3.7/site-packages/matplotlib/backend_bases.py\u001b[0m in \u001b[0;36mprint_figure\u001b[0;34m(self, filename, dpi, facecolor, edgecolor, orientation, format, bbox_inches, pad_inches, bbox_extra_artists, backend, **kwargs)\u001b[0m\n\u001b[1;32m   2290\u001b[0m                     \u001b[0mself\u001b[0m\u001b[0;34m.\u001b[0m\u001b[0mfigure\u001b[0m\u001b[0;34m,\u001b[0m\u001b[0;34m\u001b[0m\u001b[0;34m\u001b[0m\u001b[0m\n\u001b[1;32m   2291\u001b[0m                     functools.partial(\n\u001b[0;32m-> 2292\u001b[0;31m                         print_method, orientation=orientation)\n\u001b[0m\u001b[1;32m   2293\u001b[0m                 )\n\u001b[1;32m   2294\u001b[0m                 \u001b[0;32mwith\u001b[0m \u001b[0mgetattr\u001b[0m\u001b[0;34m(\u001b[0m\u001b[0mrenderer\u001b[0m\u001b[0;34m,\u001b[0m \u001b[0;34m\"_draw_disabled\"\u001b[0m\u001b[0;34m,\u001b[0m \u001b[0mnullcontext\u001b[0m\u001b[0;34m)\u001b[0m\u001b[0;34m(\u001b[0m\u001b[0;34m)\u001b[0m\u001b[0;34m:\u001b[0m\u001b[0;34m\u001b[0m\u001b[0;34m\u001b[0m\u001b[0m\n",
      "\u001b[0;32m/opt/conda/lib/python3.7/site-packages/matplotlib/backend_bases.py\u001b[0m in \u001b[0;36m_get_renderer\u001b[0;34m(figure, print_method)\u001b[0m\n\u001b[1;32m   1542\u001b[0m                 figure.canvas._get_output_canvas(None, fmt), f\"print_{fmt}\")\n\u001b[1;32m   1543\u001b[0m         \u001b[0;32mtry\u001b[0m\u001b[0;34m:\u001b[0m\u001b[0;34m\u001b[0m\u001b[0;34m\u001b[0m\u001b[0m\n\u001b[0;32m-> 1544\u001b[0;31m             \u001b[0mprint_method\u001b[0m\u001b[0;34m(\u001b[0m\u001b[0mio\u001b[0m\u001b[0;34m.\u001b[0m\u001b[0mBytesIO\u001b[0m\u001b[0;34m(\u001b[0m\u001b[0;34m)\u001b[0m\u001b[0;34m)\u001b[0m\u001b[0;34m\u001b[0m\u001b[0;34m\u001b[0m\u001b[0m\n\u001b[0m\u001b[1;32m   1545\u001b[0m         \u001b[0;32mexcept\u001b[0m \u001b[0mDone\u001b[0m \u001b[0;32mas\u001b[0m \u001b[0mexc\u001b[0m\u001b[0;34m:\u001b[0m\u001b[0;34m\u001b[0m\u001b[0;34m\u001b[0m\u001b[0m\n\u001b[1;32m   1546\u001b[0m             \u001b[0mrenderer\u001b[0m\u001b[0;34m,\u001b[0m \u001b[0;34m=\u001b[0m \u001b[0mfigure\u001b[0m\u001b[0;34m.\u001b[0m\u001b[0m_cachedRenderer\u001b[0m\u001b[0;34m,\u001b[0m \u001b[0;34m=\u001b[0m \u001b[0mexc\u001b[0m\u001b[0;34m.\u001b[0m\u001b[0margs\u001b[0m\u001b[0;34m\u001b[0m\u001b[0;34m\u001b[0m\u001b[0m\n",
      "\u001b[0;32m/opt/conda/lib/python3.7/site-packages/matplotlib/backend_bases.py\u001b[0m in \u001b[0;36mwrapper\u001b[0;34m(*args, **kwargs)\u001b[0m\n\u001b[1;32m   1646\u001b[0m             \u001b[0mkwargs\u001b[0m\u001b[0;34m.\u001b[0m\u001b[0mpop\u001b[0m\u001b[0;34m(\u001b[0m\u001b[0marg\u001b[0m\u001b[0;34m)\u001b[0m\u001b[0;34m\u001b[0m\u001b[0;34m\u001b[0m\u001b[0m\n\u001b[1;32m   1647\u001b[0m \u001b[0;34m\u001b[0m\u001b[0m\n\u001b[0;32m-> 1648\u001b[0;31m         \u001b[0;32mreturn\u001b[0m \u001b[0mfunc\u001b[0m\u001b[0;34m(\u001b[0m\u001b[0;34m*\u001b[0m\u001b[0margs\u001b[0m\u001b[0;34m,\u001b[0m \u001b[0;34m**\u001b[0m\u001b[0mkwargs\u001b[0m\u001b[0;34m)\u001b[0m\u001b[0;34m\u001b[0m\u001b[0;34m\u001b[0m\u001b[0m\n\u001b[0m\u001b[1;32m   1649\u001b[0m \u001b[0;34m\u001b[0m\u001b[0m\n\u001b[1;32m   1650\u001b[0m     \u001b[0;32mreturn\u001b[0m \u001b[0mwrapper\u001b[0m\u001b[0;34m\u001b[0m\u001b[0;34m\u001b[0m\u001b[0m\n",
      "\u001b[0;32m/opt/conda/lib/python3.7/site-packages/matplotlib/_api/deprecation.py\u001b[0m in \u001b[0;36mwrapper\u001b[0;34m(*inner_args, **inner_kwargs)\u001b[0m\n\u001b[1;32m    413\u001b[0m                          \u001b[0;32melse\u001b[0m \u001b[0mdeprecation_addendum\u001b[0m\u001b[0;34m,\u001b[0m\u001b[0;34m\u001b[0m\u001b[0;34m\u001b[0m\u001b[0m\n\u001b[1;32m    414\u001b[0m                 **kwargs)\n\u001b[0;32m--> 415\u001b[0;31m         \u001b[0;32mreturn\u001b[0m \u001b[0mfunc\u001b[0m\u001b[0;34m(\u001b[0m\u001b[0;34m*\u001b[0m\u001b[0minner_args\u001b[0m\u001b[0;34m,\u001b[0m \u001b[0;34m**\u001b[0m\u001b[0minner_kwargs\u001b[0m\u001b[0;34m)\u001b[0m\u001b[0;34m\u001b[0m\u001b[0;34m\u001b[0m\u001b[0m\n\u001b[0m\u001b[1;32m    416\u001b[0m \u001b[0;34m\u001b[0m\u001b[0m\n\u001b[1;32m    417\u001b[0m     \u001b[0mDECORATORS\u001b[0m\u001b[0;34m[\u001b[0m\u001b[0mwrapper\u001b[0m\u001b[0;34m]\u001b[0m \u001b[0;34m=\u001b[0m \u001b[0mdecorator\u001b[0m\u001b[0;34m\u001b[0m\u001b[0;34m\u001b[0m\u001b[0m\n",
      "\u001b[0;32m/opt/conda/lib/python3.7/site-packages/matplotlib/backends/backend_agg.py\u001b[0m in \u001b[0;36mprint_png\u001b[0;34m(self, filename_or_obj, metadata, pil_kwargs, *args)\u001b[0m\n\u001b[1;32m    538\u001b[0m             \u001b[0;34m*\u001b[0m\u001b[0mmetadata\u001b[0m\u001b[0;34m*\u001b[0m\u001b[0;34m,\u001b[0m \u001b[0mincluding\u001b[0m \u001b[0mthe\u001b[0m \u001b[0mdefault\u001b[0m \u001b[0;34m'Software'\u001b[0m \u001b[0mkey\u001b[0m\u001b[0;34m.\u001b[0m\u001b[0;34m\u001b[0m\u001b[0;34m\u001b[0m\u001b[0m\n\u001b[1;32m    539\u001b[0m         \"\"\"\n\u001b[0;32m--> 540\u001b[0;31m         \u001b[0mFigureCanvasAgg\u001b[0m\u001b[0;34m.\u001b[0m\u001b[0mdraw\u001b[0m\u001b[0;34m(\u001b[0m\u001b[0mself\u001b[0m\u001b[0;34m)\u001b[0m\u001b[0;34m\u001b[0m\u001b[0;34m\u001b[0m\u001b[0m\n\u001b[0m\u001b[1;32m    541\u001b[0m         mpl.image.imsave(\n\u001b[1;32m    542\u001b[0m             \u001b[0mfilename_or_obj\u001b[0m\u001b[0;34m,\u001b[0m \u001b[0mself\u001b[0m\u001b[0;34m.\u001b[0m\u001b[0mbuffer_rgba\u001b[0m\u001b[0;34m(\u001b[0m\u001b[0;34m)\u001b[0m\u001b[0;34m,\u001b[0m \u001b[0mformat\u001b[0m\u001b[0;34m=\u001b[0m\u001b[0;34m\"png\"\u001b[0m\u001b[0;34m,\u001b[0m \u001b[0morigin\u001b[0m\u001b[0;34m=\u001b[0m\u001b[0;34m\"upper\"\u001b[0m\u001b[0;34m,\u001b[0m\u001b[0;34m\u001b[0m\u001b[0;34m\u001b[0m\u001b[0m\n",
      "\u001b[0;32m/opt/conda/lib/python3.7/site-packages/matplotlib/backends/backend_agg.py\u001b[0m in \u001b[0;36mdraw\u001b[0;34m(self)\u001b[0m\n\u001b[1;32m    429\u001b[0m     \u001b[0;32mdef\u001b[0m \u001b[0mdraw\u001b[0m\u001b[0;34m(\u001b[0m\u001b[0mself\u001b[0m\u001b[0;34m)\u001b[0m\u001b[0;34m:\u001b[0m\u001b[0;34m\u001b[0m\u001b[0;34m\u001b[0m\u001b[0m\n\u001b[1;32m    430\u001b[0m         \u001b[0;31m# docstring inherited\u001b[0m\u001b[0;34m\u001b[0m\u001b[0;34m\u001b[0m\u001b[0;34m\u001b[0m\u001b[0m\n\u001b[0;32m--> 431\u001b[0;31m         \u001b[0mself\u001b[0m\u001b[0;34m.\u001b[0m\u001b[0mrenderer\u001b[0m \u001b[0;34m=\u001b[0m \u001b[0mself\u001b[0m\u001b[0;34m.\u001b[0m\u001b[0mget_renderer\u001b[0m\u001b[0;34m(\u001b[0m\u001b[0mcleared\u001b[0m\u001b[0;34m=\u001b[0m\u001b[0;32mTrue\u001b[0m\u001b[0;34m)\u001b[0m\u001b[0;34m\u001b[0m\u001b[0;34m\u001b[0m\u001b[0m\n\u001b[0m\u001b[1;32m    432\u001b[0m         \u001b[0;31m# Acquire a lock on the shared font cache.\u001b[0m\u001b[0;34m\u001b[0m\u001b[0;34m\u001b[0m\u001b[0;34m\u001b[0m\u001b[0m\n\u001b[1;32m    433\u001b[0m         \u001b[0;32mwith\u001b[0m \u001b[0mRendererAgg\u001b[0m\u001b[0;34m.\u001b[0m\u001b[0mlock\u001b[0m\u001b[0;34m,\u001b[0m\u001b[0;31m \u001b[0m\u001b[0;31m\\\u001b[0m\u001b[0;34m\u001b[0m\u001b[0;34m\u001b[0m\u001b[0m\n",
      "\u001b[0;32m/opt/conda/lib/python3.7/site-packages/matplotlib/backends/backend_agg.py\u001b[0m in \u001b[0;36mget_renderer\u001b[0;34m(self, cleared)\u001b[0m\n\u001b[1;32m    445\u001b[0m                           and getattr(self, \"_lastKey\", None) == key)\n\u001b[1;32m    446\u001b[0m         \u001b[0;32mif\u001b[0m \u001b[0;32mnot\u001b[0m \u001b[0mreuse_renderer\u001b[0m\u001b[0;34m:\u001b[0m\u001b[0;34m\u001b[0m\u001b[0;34m\u001b[0m\u001b[0m\n\u001b[0;32m--> 447\u001b[0;31m             \u001b[0mself\u001b[0m\u001b[0;34m.\u001b[0m\u001b[0mrenderer\u001b[0m \u001b[0;34m=\u001b[0m \u001b[0mRendererAgg\u001b[0m\u001b[0;34m(\u001b[0m\u001b[0mw\u001b[0m\u001b[0;34m,\u001b[0m \u001b[0mh\u001b[0m\u001b[0;34m,\u001b[0m \u001b[0mself\u001b[0m\u001b[0;34m.\u001b[0m\u001b[0mfigure\u001b[0m\u001b[0;34m.\u001b[0m\u001b[0mdpi\u001b[0m\u001b[0;34m)\u001b[0m\u001b[0;34m\u001b[0m\u001b[0;34m\u001b[0m\u001b[0m\n\u001b[0m\u001b[1;32m    448\u001b[0m             \u001b[0mself\u001b[0m\u001b[0;34m.\u001b[0m\u001b[0m_lastKey\u001b[0m \u001b[0;34m=\u001b[0m \u001b[0mkey\u001b[0m\u001b[0;34m\u001b[0m\u001b[0;34m\u001b[0m\u001b[0m\n\u001b[1;32m    449\u001b[0m         \u001b[0;32melif\u001b[0m \u001b[0mcleared\u001b[0m\u001b[0;34m:\u001b[0m\u001b[0;34m\u001b[0m\u001b[0;34m\u001b[0m\u001b[0m\n",
      "\u001b[0;32m/opt/conda/lib/python3.7/site-packages/matplotlib/backends/backend_agg.py\u001b[0m in \u001b[0;36m__init__\u001b[0;34m(self, width, height, dpi)\u001b[0m\n\u001b[1;32m     91\u001b[0m         \u001b[0mself\u001b[0m\u001b[0;34m.\u001b[0m\u001b[0mwidth\u001b[0m \u001b[0;34m=\u001b[0m \u001b[0mwidth\u001b[0m\u001b[0;34m\u001b[0m\u001b[0;34m\u001b[0m\u001b[0m\n\u001b[1;32m     92\u001b[0m         \u001b[0mself\u001b[0m\u001b[0;34m.\u001b[0m\u001b[0mheight\u001b[0m \u001b[0;34m=\u001b[0m \u001b[0mheight\u001b[0m\u001b[0;34m\u001b[0m\u001b[0;34m\u001b[0m\u001b[0m\n\u001b[0;32m---> 93\u001b[0;31m         \u001b[0mself\u001b[0m\u001b[0;34m.\u001b[0m\u001b[0m_renderer\u001b[0m \u001b[0;34m=\u001b[0m \u001b[0m_RendererAgg\u001b[0m\u001b[0;34m(\u001b[0m\u001b[0mint\u001b[0m\u001b[0;34m(\u001b[0m\u001b[0mwidth\u001b[0m\u001b[0;34m)\u001b[0m\u001b[0;34m,\u001b[0m \u001b[0mint\u001b[0m\u001b[0;34m(\u001b[0m\u001b[0mheight\u001b[0m\u001b[0;34m)\u001b[0m\u001b[0;34m,\u001b[0m \u001b[0mdpi\u001b[0m\u001b[0;34m)\u001b[0m\u001b[0;34m\u001b[0m\u001b[0;34m\u001b[0m\u001b[0m\n\u001b[0m\u001b[1;32m     94\u001b[0m         \u001b[0mself\u001b[0m\u001b[0;34m.\u001b[0m\u001b[0m_filter_renderers\u001b[0m \u001b[0;34m=\u001b[0m \u001b[0;34m[\u001b[0m\u001b[0;34m]\u001b[0m\u001b[0;34m\u001b[0m\u001b[0;34m\u001b[0m\u001b[0m\n\u001b[1;32m     95\u001b[0m \u001b[0;34m\u001b[0m\u001b[0m\n",
      "\u001b[0;31mMemoryError\u001b[0m: In RendererAgg: Out of memory"
     ]
    },
    {
     "data": {
      "text/plain": [
       "<Figure size 576x432 with 1 Axes>"
      ]
     },
     "metadata": {},
     "output_type": "display_data"
    }
   ],
   "source": [
    "plt.figure(figsize=(8, 6), facecolor=\"azure\")\n",
    "for label in np.unique(test_labels):\n",
    "    tmp = test_results[test_labels==label]\n",
    "    plt.scatter(tmp[:, 0], tmp[:, 1], label=label)\n",
    "\n",
    "plt.legend()\n",
    "plt.show()"
   ]
  },
  {
   "cell_type": "code",
   "execution_count": 36,
   "metadata": {
    "execution": {
     "iopub.execute_input": "2022-11-26T05:02:38.576521Z",
     "iopub.status.busy": "2022-11-26T05:02:38.576048Z",
     "iopub.status.idle": "2022-11-26T05:02:38.583621Z",
     "shell.execute_reply": "2022-11-26T05:02:38.581255Z",
     "shell.execute_reply.started": "2022-11-26T05:02:38.576454Z"
    }
   },
   "outputs": [],
   "source": [
    "clf_lr_1 = LogisticRegression(max_iter=5000, C=1, penalty='l2', solver='liblinear')"
   ]
  },
  {
   "cell_type": "code",
   "execution_count": null,
   "metadata": {
    "execution": {
     "iopub.execute_input": "2022-11-26T05:02:38.588499Z",
     "iopub.status.busy": "2022-11-26T05:02:38.587022Z",
     "iopub.status.idle": "2022-11-26T05:02:38.677724Z"
    }
   },
   "outputs": [
    {
     "name": "stdout",
     "output_type": "stream",
     "text": [
      "Traceback (most recent call last):\n",
      "  File \"/opt/conda/lib/python3.7/site-packages/IPython/core/interactiveshell.py\", line 3552, in run_code\n",
      "    exec(code_obj, self.user_global_ns, self.user_ns)\n",
      "  File \"/tmp/ipykernel_3451/1838510596.py\", line 14, in <module>\n",
      "    clf_lr_1.fit(X_train_t, y_train_t)\n",
      "  File \"/opt/conda/lib/python3.7/site-packages/sklearn/linear_model/_logistic.py\", line 1514, in fit\n",
      "    accept_large_sparse=solver not in [\"liblinear\", \"sag\", \"saga\"],\n",
      "  File \"/opt/conda/lib/python3.7/site-packages/sklearn/base.py\", line 581, in _validate_data\n",
      "    X, y = check_X_y(X, y, **check_params)\n",
      "  File \"/opt/conda/lib/python3.7/site-packages/sklearn/utils/validation.py\", line 976, in check_X_y\n",
      "    estimator=estimator,\n",
      "  File \"/opt/conda/lib/python3.7/site-packages/sklearn/utils/validation.py\", line 773, in check_array\n",
      "    \"if it contains a single sample.\".format(array)\n",
      "ValueError: Expected 2D array, got 1D array instead:\n",
      "array=[].\n",
      "Reshape your data either using array.reshape(-1, 1) if your data has a single feature or array.reshape(1, -1) if it contains a single sample.\n",
      "\n",
      "During handling of the above exception, another exception occurred:\n",
      "\n",
      "Traceback (most recent call last):\n",
      "  File \"/opt/conda/lib/python3.7/site-packages/IPython/core/interactiveshell.py\", line 2098, in showtraceback\n",
      "    stb = value._render_traceback_()\n",
      "AttributeError: 'ValueError' object has no attribute '_render_traceback_'\n",
      "\n",
      "During handling of the above exception, another exception occurred:\n",
      "\n",
      "Traceback (most recent call last):\n",
      "  File \"/opt/conda/lib/python3.7/site-packages/IPython/core/ultratb.py\", line 1101, in get_records\n",
      "    return _fixed_getinnerframes(etb, number_of_lines_of_context, tb_offset)\n",
      "  File \"/opt/conda/lib/python3.7/site-packages/IPython/core/ultratb.py\", line 248, in wrapped\n",
      "    return f(*args, **kwargs)\n",
      "  File \"/opt/conda/lib/python3.7/site-packages/IPython/core/ultratb.py\", line 281, in _fixed_getinnerframes\n",
      "    records = fix_frame_records_filenames(inspect.getinnerframes(etb, context))\n",
      "  File \"/opt/conda/lib/python3.7/inspect.py\", line 1502, in getinnerframes\n",
      "    frameinfo = (tb.tb_frame,) + getframeinfo(tb, context)\n",
      "  File \"/opt/conda/lib/python3.7/inspect.py\", line 1460, in getframeinfo\n",
      "    filename = getsourcefile(frame) or getfile(frame)\n",
      "  File \"/opt/conda/lib/python3.7/inspect.py\", line 696, in getsourcefile\n",
      "    if getattr(getmodule(object, filename), '__loader__', None) is not None:\n",
      "  File \"/opt/conda/lib/python3.7/inspect.py\", line 732, in getmodule\n",
      "    for modname, module in sys.modules.copy().items():\n",
      "MemoryError\n",
      "Traceback (most recent call last):\n",
      "  File \"/opt/conda/lib/python3.7/site-packages/IPython/core/interactiveshell.py\", line 3552, in run_code\n",
      "    exec(code_obj, self.user_global_ns, self.user_ns)\n",
      "  File \"/tmp/ipykernel_3451/1838510596.py\", line 14, in <module>\n",
      "    clf_lr_1.fit(X_train_t, y_train_t)\n",
      "  File \"/opt/conda/lib/python3.7/site-packages/sklearn/linear_model/_logistic.py\", line 1514, in fit\n",
      "    accept_large_sparse=solver not in [\"liblinear\", \"sag\", \"saga\"],\n",
      "  File \"/opt/conda/lib/python3.7/site-packages/sklearn/base.py\", line 581, in _validate_data\n",
      "    X, y = check_X_y(X, y, **check_params)\n",
      "  File \"/opt/conda/lib/python3.7/site-packages/sklearn/utils/validation.py\", line 976, in check_X_y\n",
      "    estimator=estimator,\n",
      "  File \"/opt/conda/lib/python3.7/site-packages/sklearn/utils/validation.py\", line 773, in check_array\n",
      "    \"if it contains a single sample.\".format(array)\n",
      "ValueError: Expected 2D array, got 1D array instead:\n",
      "array=[].\n",
      "Reshape your data either using array.reshape(-1, 1) if your data has a single feature or array.reshape(1, -1) if it contains a single sample.\n",
      "\n",
      "During handling of the above exception, another exception occurred:\n",
      "\n",
      "Traceback (most recent call last):\n",
      "  File \"/opt/conda/lib/python3.7/site-packages/IPython/core/interactiveshell.py\", line 2098, in showtraceback\n",
      "    stb = value._render_traceback_()\n",
      "AttributeError: 'ValueError' object has no attribute '_render_traceback_'\n",
      "\n",
      "During handling of the above exception, another exception occurred:\n",
      "\n",
      "Traceback (most recent call last):\n",
      "  File \"/opt/conda/lib/python3.7/site-packages/IPython/core/interactiveshell.py\", line 3472, in run_ast_nodes\n",
      "    if (await self.run_code(code, result,  async_=asy)):\n",
      "  File \"/opt/conda/lib/python3.7/site-packages/IPython/core/interactiveshell.py\", line 3569, in run_code\n",
      "    self.showtraceback(running_compiled_code=True)\n",
      "  File \"/opt/conda/lib/python3.7/site-packages/IPython/core/interactiveshell.py\", line 2101, in showtraceback\n",
      "    value, tb, tb_offset=tb_offset)\n",
      "  File \"/opt/conda/lib/python3.7/site-packages/IPython/core/ultratb.py\", line 1368, in structured_traceback\n",
      "    self, etype, value, tb, tb_offset, number_of_lines_of_context)\n",
      "  File \"/opt/conda/lib/python3.7/site-packages/IPython/core/ultratb.py\", line 1268, in structured_traceback\n",
      "    self, etype, value, tb, tb_offset, number_of_lines_of_context\n",
      "  File \"/opt/conda/lib/python3.7/site-packages/IPython/core/ultratb.py\", line 1125, in structured_traceback\n",
      "    tb_offset)\n",
      "  File \"/opt/conda/lib/python3.7/site-packages/IPython/core/ultratb.py\", line 1082, in format_exception_as_a_whole\n",
      "    last_unique, recursion_repeat = find_recursion(orig_etype, evalue, records)\n",
      "  File \"/opt/conda/lib/python3.7/site-packages/IPython/core/ultratb.py\", line 382, in find_recursion\n",
      "    return len(records), 0\n",
      "TypeError: object of type 'NoneType' has no len()\n",
      "\n",
      "During handling of the above exception, another exception occurred:\n",
      "\n",
      "Traceback (most recent call last):\n",
      "  File \"/opt/conda/lib/python3.7/site-packages/IPython/core/interactiveshell.py\", line 2098, in showtraceback\n",
      "    stb = value._render_traceback_()\n",
      "AttributeError: 'TypeError' object has no attribute '_render_traceback_'\n",
      "\n",
      "During handling of the above exception, another exception occurred:\n",
      "\n",
      "Traceback (most recent call last):\n",
      "  File \"/opt/conda/lib/python3.7/site-packages/IPython/core/ultratb.py\", line 1101, in get_records\n",
      "    return _fixed_getinnerframes(etb, number_of_lines_of_context, tb_offset)\n",
      "  File \"/opt/conda/lib/python3.7/site-packages/IPython/core/ultratb.py\", line 248, in wrapped\n",
      "    return f(*args, **kwargs)\n",
      "  File \"/opt/conda/lib/python3.7/site-packages/IPython/core/ultratb.py\", line 281, in _fixed_getinnerframes\n",
      "    records = fix_frame_records_filenames(inspect.getinnerframes(etb, context))\n",
      "  File \"/opt/conda/lib/python3.7/inspect.py\", line 1502, in getinnerframes\n",
      "    frameinfo = (tb.tb_frame,) + getframeinfo(tb, context)\n",
      "  File \"/opt/conda/lib/python3.7/inspect.py\", line 1460, in getframeinfo\n",
      "    filename = getsourcefile(frame) or getfile(frame)\n",
      "  File \"/opt/conda/lib/python3.7/inspect.py\", line 696, in getsourcefile\n",
      "    if getattr(getmodule(object, filename), '__loader__', None) is not None:\n",
      "  File \"/opt/conda/lib/python3.7/inspect.py\", line 732, in getmodule\n",
      "    for modname, module in sys.modules.copy().items():\n",
      "MemoryError\n",
      "Traceback (most recent call last):\n",
      "  File \"/opt/conda/lib/python3.7/site-packages/IPython/core/interactiveshell.py\", line 3552, in run_code\n",
      "    exec(code_obj, self.user_global_ns, self.user_ns)\n",
      "  File \"/tmp/ipykernel_3451/1838510596.py\", line 14, in <module>\n",
      "    clf_lr_1.fit(X_train_t, y_train_t)\n",
      "  File \"/opt/conda/lib/python3.7/site-packages/sklearn/linear_model/_logistic.py\", line 1514, in fit\n",
      "    accept_large_sparse=solver not in [\"liblinear\", \"sag\", \"saga\"],\n",
      "  File \"/opt/conda/lib/python3.7/site-packages/sklearn/base.py\", line 581, in _validate_data\n",
      "    X, y = check_X_y(X, y, **check_params)\n",
      "  File \"/opt/conda/lib/python3.7/site-packages/sklearn/utils/validation.py\", line 976, in check_X_y\n",
      "    estimator=estimator,\n",
      "  File \"/opt/conda/lib/python3.7/site-packages/sklearn/utils/validation.py\", line 773, in check_array\n",
      "    \"if it contains a single sample.\".format(array)\n",
      "ValueError: Expected 2D array, got 1D array instead:\n",
      "array=[].\n",
      "Reshape your data either using array.reshape(-1, 1) if your data has a single feature or array.reshape(1, -1) if it contains a single sample.\n",
      "\n",
      "During handling of the above exception, another exception occurred:\n",
      "\n",
      "Traceback (most recent call last):\n",
      "  File \"/opt/conda/lib/python3.7/site-packages/IPython/core/interactiveshell.py\", line 2098, in showtraceback\n",
      "    stb = value._render_traceback_()\n",
      "AttributeError: 'ValueError' object has no attribute '_render_traceback_'\n",
      "\n",
      "During handling of the above exception, another exception occurred:\n",
      "\n",
      "Traceback (most recent call last):\n",
      "  File \"/opt/conda/lib/python3.7/site-packages/IPython/core/interactiveshell.py\", line 3472, in run_ast_nodes\n",
      "    if (await self.run_code(code, result,  async_=asy)):\n",
      "  File \"/opt/conda/lib/python3.7/site-packages/IPython/core/interactiveshell.py\", line 3569, in run_code\n",
      "    self.showtraceback(running_compiled_code=True)\n",
      "  File \"/opt/conda/lib/python3.7/site-packages/IPython/core/interactiveshell.py\", line 2101, in showtraceback\n",
      "    value, tb, tb_offset=tb_offset)\n",
      "  File \"/opt/conda/lib/python3.7/site-packages/IPython/core/ultratb.py\", line 1368, in structured_traceback\n",
      "    self, etype, value, tb, tb_offset, number_of_lines_of_context)\n",
      "  File \"/opt/conda/lib/python3.7/site-packages/IPython/core/ultratb.py\", line 1268, in structured_traceback\n",
      "    self, etype, value, tb, tb_offset, number_of_lines_of_context\n",
      "  File \"/opt/conda/lib/python3.7/site-packages/IPython/core/ultratb.py\", line 1125, in structured_traceback\n",
      "    tb_offset)\n",
      "  File \"/opt/conda/lib/python3.7/site-packages/IPython/core/ultratb.py\", line 1082, in format_exception_as_a_whole\n",
      "    last_unique, recursion_repeat = find_recursion(orig_etype, evalue, records)\n",
      "  File \"/opt/conda/lib/python3.7/site-packages/IPython/core/ultratb.py\", line 382, in find_recursion\n",
      "    return len(records), 0\n",
      "TypeError: object of type 'NoneType' has no len()\n",
      "\n",
      "During handling of the above exception, another exception occurred:\n",
      "\n",
      "Traceback (most recent call last):\n",
      "  File \"/opt/conda/lib/python3.7/site-packages/IPython/core/interactiveshell.py\", line 2098, in showtraceback\n",
      "    stb = value._render_traceback_()\n",
      "AttributeError: 'TypeError' object has no attribute '_render_traceback_'\n",
      "\n",
      "During handling of the above exception, another exception occurred:\n",
      "\n",
      "Traceback (most recent call last):\n",
      "  File \"/opt/conda/lib/python3.7/site-packages/IPython/core/interactiveshell.py\", line 3029, in _run_cell\n",
      "    return runner(coro)\n",
      "  File \"/opt/conda/lib/python3.7/site-packages/IPython/core/async_helpers.py\", line 78, in _pseudo_sync_runner\n",
      "    coro.send(None)\n",
      "  File \"/opt/conda/lib/python3.7/site-packages/IPython/core/interactiveshell.py\", line 3257, in run_cell_async\n",
      "    interactivity=interactivity, compiler=compiler, result=result)\n",
      "  File \"/opt/conda/lib/python3.7/site-packages/IPython/core/interactiveshell.py\", line 3491, in run_ast_nodes\n",
      "    self.showtraceback()\n",
      "  File \"/opt/conda/lib/python3.7/site-packages/IPython/core/interactiveshell.py\", line 2101, in showtraceback\n",
      "    value, tb, tb_offset=tb_offset)\n",
      "  File \"/opt/conda/lib/python3.7/site-packages/IPython/core/ultratb.py\", line 1368, in structured_traceback\n",
      "    self, etype, value, tb, tb_offset, number_of_lines_of_context)\n",
      "  File \"/opt/conda/lib/python3.7/site-packages/IPython/core/ultratb.py\", line 1268, in structured_traceback\n",
      "    self, etype, value, tb, tb_offset, number_of_lines_of_context\n",
      "  File \"/opt/conda/lib/python3.7/site-packages/IPython/core/ultratb.py\", line 1143, in structured_traceback\n",
      "    chained_exceptions_tb_offset)\n",
      "  File \"/opt/conda/lib/python3.7/site-packages/IPython/core/ultratb.py\", line 1082, in format_exception_as_a_whole\n",
      "    last_unique, recursion_repeat = find_recursion(orig_etype, evalue, records)\n",
      "  File \"/opt/conda/lib/python3.7/site-packages/IPython/core/ultratb.py\", line 382, in find_recursion\n",
      "    return len(records), 0\n",
      "TypeError: object of type 'NoneType' has no len()\n",
      "\n",
      "During handling of the above exception, another exception occurred:\n",
      "\n",
      "Traceback (most recent call last):\n",
      "  File \"/opt/conda/lib/python3.7/site-packages/IPython/core/interactiveshell.py\", line 2098, in showtraceback\n",
      "    stb = value._render_traceback_()\n",
      "AttributeError: 'TypeError' object has no attribute '_render_traceback_'\n",
      "\n",
      "During handling of the above exception, another exception occurred:\n",
      "\n",
      "Traceback (most recent call last):\n",
      "  File \"/opt/conda/lib/python3.7/site-packages/IPython/core/ultratb.py\", line 1101, in get_records\n",
      "    return _fixed_getinnerframes(etb, number_of_lines_of_context, tb_offset)\n",
      "  File \"/opt/conda/lib/python3.7/site-packages/IPython/core/ultratb.py\", line 248, in wrapped\n",
      "    return f(*args, **kwargs)\n",
      "  File \"/opt/conda/lib/python3.7/site-packages/IPython/core/ultratb.py\", line 281, in _fixed_getinnerframes\n",
      "    records = fix_frame_records_filenames(inspect.getinnerframes(etb, context))\n",
      "  File \"/opt/conda/lib/python3.7/inspect.py\", line 1502, in getinnerframes\n",
      "    frameinfo = (tb.tb_frame,) + getframeinfo(tb, context)\n",
      "  File \"/opt/conda/lib/python3.7/inspect.py\", line 1460, in getframeinfo\n",
      "    filename = getsourcefile(frame) or getfile(frame)\n",
      "  File \"/opt/conda/lib/python3.7/inspect.py\", line 696, in getsourcefile\n",
      "    if getattr(getmodule(object, filename), '__loader__', None) is not None:\n",
      "  File \"/opt/conda/lib/python3.7/inspect.py\", line 732, in getmodule\n",
      "    for modname, module in sys.modules.copy().items():\n",
      "MemoryError\n"
     ]
    }
   ],
   "source": [
    "results = {\n",
    "    'test_accuracy' : [],\n",
    "    'test_precision' : [],\n",
    "    'test_recall' : [],\n",
    "    'test_f1' : []\n",
    "}\n",
    "\n",
    "\n",
    "y_train_t = labels\n",
    "X_train_t = train_results\n",
    "y_test_t = test_labels\n",
    "X_test_t = test_results\n",
    "\n",
    "clf_lr_1.fit(X_train_t, y_train_t)\n",
    "\n",
    "y_pred = clf_lr_1.predict(X_test_t)\n",
    "\n",
    "results['test_accuracy'].append( accuracy_score(y_test_t, y_pred) ) \n",
    "results['test_precision'].append( precision_score(y_test_t, y_pred) ) \n",
    "results['test_recall'].append( recall_score(y_test_t, y_pred) ) \n",
    "results['test_f1'].append( f1_score(y_test_t, y_pred) ) \n",
    "\n",
    "metrics = {\n",
    "    \"Accuracy\": np.array(results['test_accuracy']),\n",
    "#     \"Precision\": np.array(results['test_precision']).mean(),\n",
    "#     \"Recall\": np.array(results['test_recall']).mean(),\n",
    "    \"F1 Score\":  np.array(results['test_f1']),\n",
    "    }"
   ]
  },
  {
   "cell_type": "code",
   "execution_count": 37,
   "metadata": {
    "execution": {
     "iopub.execute_input": "2022-11-26T05:02:38.681372Z",
     "iopub.status.busy": "2022-11-26T05:02:38.679735Z",
     "iopub.status.idle": "2022-11-26T05:02:38.693498Z",
     "shell.execute_reply": "2022-11-26T05:02:38.690395Z",
     "shell.execute_reply.started": "2022-11-26T05:02:38.681295Z"
    }
   },
   "outputs": [
    {
     "ename": "MemoryError",
     "evalue": "",
     "output_type": "error",
     "traceback": [
      "\u001b[0;31mMemoryError\u001b[0m\n"
     ]
    }
   ],
   "source": [
    "confusion_matrix(y_test_t, y_pred)"
   ]
  },
  {
   "cell_type": "code",
   "execution_count": null,
   "metadata": {
    "execution": {
     "iopub.status.busy": "2022-11-26T05:02:38.694941Z",
     "iopub.status.idle": "2022-11-26T05:02:38.695745Z",
     "shell.execute_reply": "2022-11-26T05:02:38.695316Z",
     "shell.execute_reply.started": "2022-11-26T05:02:38.695278Z"
    }
   },
   "outputs": [
    {
     "name": "stdout",
     "output_type": "stream",
     "text": [
      "ERROR! Session/line number was not unique in database. History logging moved to new session 10\n"
     ]
    }
   ],
   "source": [
    "metrics"
   ]
  },
  {
   "cell_type": "markdown",
   "metadata": {},
   "source": [
    "# Test using CV"
   ]
  },
  {
   "cell_type": "code",
   "execution_count": null,
   "metadata": {
    "execution": {
     "iopub.status.busy": "2022-11-26T00:19:12.905729Z",
     "iopub.status.idle": "2022-11-26T00:19:12.906226Z",
     "shell.execute_reply": "2022-11-26T00:19:12.906001Z",
     "shell.execute_reply.started": "2022-11-26T00:19:12.905976Z"
    }
   },
   "outputs": [],
   "source": [
    "results = {\n",
    "    'test_accuracy' : [],\n",
    "    'test_precision' : [],\n",
    "    'test_recall' : [],\n",
    "    'test_f1' : []\n",
    "}\n",
    "\n",
    "embedding_dims = 100\n",
    "batch_size = 128\n",
    "epochs = 500\n",
    "lr = 0.001\n",
    "\n",
    "for j, (train_index, val_index, test_index) in enumerate(cv_fold_i):\n",
    "    train_ds = FakeNews(embeddings_table, df['assestment'].values, train_index)\n",
    "    train_loader = DataLoader(train_ds, batch_size=batch_size, shuffle=True, num_workers=2)\n",
    "    \n",
    "    val_ds = FakeNews(embeddings_table, df['assestment'].values, val_index)\n",
    "    val_loader = DataLoader(val_ds, batch_size=batch_size, shuffle=True, num_workers=2)\n",
    "\n",
    "    test_ds = FakeNews(embeddings_table, df['assestment'].values, test_index)\n",
    "    test_loader = DataLoader(test_ds, batch_size=batch_size//2, shuffle=False, num_workers=2)\n",
    "\n",
    "    \n",
    "    model = Network(embedding_dims)\n",
    "    model = model.to(device)\n",
    "\n",
    "    optimizer = optim.Adam(model.parameters(), lr=lr)\n",
    "    criterion = TripletLoss()\n",
    "\n",
    "    val_prev = np.inf\n",
    "    \n",
    "    model.train()\n",
    "    for epoch in tqdm(range(epochs), desc=f\"Epochs {j}\"):\n",
    "        running_loss = []\n",
    "        for step, (anchor_claim, positive_claim, negative_claim, anchor_label) in enumerate(train_loader):\n",
    "            anchor_claim = anchor_claim.to(device)\n",
    "            positive_claim = positive_claim.to(device)\n",
    "            negative_claim = negative_claim.to(device)\n",
    "\n",
    "            optimizer.zero_grad()\n",
    "            anchor_out = model(anchor_claim)\n",
    "            positive_out = model(positive_claim)\n",
    "            negative_out = model(negative_claim)\n",
    "\n",
    "            loss = criterion(anchor_out, positive_out, negative_out)\n",
    "            loss.backward()\n",
    "            optimizer.step()\n",
    "\n",
    "            running_loss.append(loss.cpu().detach().numpy())\n",
    "\n",
    "        model.eval()\n",
    "    \n",
    "        val_loss = []\n",
    "        for anchor_claim, positive_claim, negative_claim, _ in val_loader:\n",
    "            anchor_claim = anchor_claim.to(device)\n",
    "            positive_claim = positive_claim.to(device)\n",
    "            negative_claim = negative_claim.to(device)\n",
    "\n",
    "            anchor_out = model(anchor_claim)\n",
    "            positive_out = model(positive_claim)\n",
    "            negative_out = model(negative_claim)\n",
    "\n",
    "            loss = criterion(anchor_out, positive_out, negative_out)\n",
    "            val_loss.append(loss.cpu().detach().numpy())\n",
    "\n",
    "        model.train()\n",
    "        \n",
    "        if np.mean(val_loss) < val_prev:\n",
    "            val_prev = np.mean(val_loss)\n",
    "            torch.save(model, f'model_cv{j}.pt')\n",
    "        \n",
    "        if epoch%100 == 0:\n",
    "            print(f\"{j} Epoch: {epoch+1}/{epochs} - Train Loss: {np.mean(running_loss):.4f};\",\n",
    "                  f\" Val Loss: {np.mean(val_loss):.4f} Val loss best {val_prev:.4f}\"\n",
    "             )\n",
    "            \n",
    "    \n",
    "    train_results = []\n",
    "    labels = []\n",
    "\n",
    "    model.eval()\n",
    "    \n",
    "    model = torch.load(f'model_cv{j}.pt')\n",
    "    model.eval()\n",
    "    with torch.no_grad():\n",
    "        for claim, _, _, label in train_loader:\n",
    "            anchor_claim = claim.to(device)\n",
    "\n",
    "            train_results.append(model(anchor_claim).cpu().numpy())\n",
    "            labels.append(label)\n",
    "\n",
    "\n",
    "    train_results = np.concatenate(train_results) \n",
    "    labels = np.concatenate(labels)\n",
    "\n",
    "    \n",
    "    test_results = []\n",
    "    test_labels = []\n",
    "\n",
    "    model.eval()\n",
    "    with torch.no_grad():\n",
    "        for claim, _, _, label in test_loader:\n",
    "            anchor_claim = claim.to(device)\n",
    "\n",
    "            test_results.append(model(anchor_claim).cpu().numpy())\n",
    "            test_labels.append(label)\n",
    "\n",
    "\n",
    "    test_results = np.concatenate(test_results)\n",
    "    test_labels = np.concatenate(test_labels)\n",
    "\n",
    "    \n",
    "    clf_lr_1 = LogisticRegression(max_iter=5000, C=1, penalty='l2', solver='liblinear')\n",
    "\n",
    "    y_train_t = labels\n",
    "    X_train_t = train_results\n",
    "    y_test_t = test_labels\n",
    "    X_test_t = test_results\n",
    "\n",
    "    clf_lr_1.fit(X_train_t, y_train_t)\n",
    "\n",
    "    y_pred = clf_lr_1.predict(X_test_t)\n",
    "\n",
    "    results['test_accuracy'].append( accuracy_score(y_test_t, y_pred) ) \n",
    "    results['test_precision'].append( precision_score(y_test_t, y_pred) ) \n",
    "    results['test_recall'].append( recall_score(y_test_t, y_pred) ) \n",
    "    results['test_f1'].append( f1_score(y_test_t, y_pred) ) \n",
    "\n",
    "\n",
    "out = {\n",
    "    \"Accuracy\": np.array(results['test_accuracy']),\n",
    "#     \"Precision\": np.array(results['test_precision']).mean(),\n",
    "#     \"Recall\": np.array(results['test_recall']).mean(),\n",
    "    \"F1 Score\":  np.array(results['test_f1']),\n",
    "    }\n",
    "\n",
    "print(\n",
    "    'triplet loss lr C1',\n",
    "    f'Accuracy {out[\"Accuracy\"].mean():.3f}+-{out[\"Accuracy\"].std():.3f}',\n",
    "    f'F1 Score {out[\"F1 Score\"].mean():.3f}+-{out[\"F1 Score\"].std():.3f}',\n",
    "    f' {out[\"Accuracy\"].mean():.3f}+-{out[\"Accuracy\"].std():.3f} | {out[\"F1 Score\"].mean():.3f}+-{out[\"F1 Score\"].std():.3f}'\n",
    ")    "
   ]
  },
  {
   "cell_type": "code",
   "execution_count": null,
   "metadata": {
    "execution": {
     "iopub.status.busy": "2022-11-25T22:33:24.463230Z",
     "iopub.status.idle": "2022-11-25T22:33:24.463762Z",
     "shell.execute_reply": "2022-11-25T22:33:24.463508Z",
     "shell.execute_reply.started": "2022-11-25T22:33:24.463483Z"
    }
   },
   "outputs": [],
   "source": [
    "results = {\n",
    "    'test_accuracy' : [],\n",
    "    'test_precision' : [],\n",
    "    'test_recall' : [],\n",
    "    'test_f1' : []\n",
    "}\n",
    "\n",
    "embedding_dims = 100\n",
    "batch_size = 128\n",
    "epochs = 1000\n",
    "lr = 0.001\n",
    "\n",
    "for j, (train_index, val_index, test_index) in enumerate(cv_Kfold_i):\n",
    "    train_ds = FakeNews(embeddings_table, df['assestment'].values, train_index)\n",
    "    train_loader = DataLoader(train_ds, batch_size=batch_size, shuffle=True, num_workers=2)\n",
    "    \n",
    "    val_ds = FakeNews(embeddings_table, df['assestment'].values, val_index)\n",
    "    val_loader = DataLoader(val_ds, batch_size=batch_size, shuffle=True, num_workers=2)\n",
    "\n",
    "    test_ds = FakeNews(embeddings_table, df['assestment'].values, test_index)\n",
    "    test_loader = DataLoader(test_ds, batch_size=batch_size//2, shuffle=False, num_workers=2)\n",
    "\n",
    "    \n",
    "    model = Network(embedding_dims)\n",
    "    model = model.to(device)\n",
    "\n",
    "    optimizer = optim.Adam(model.parameters(), lr=lr)\n",
    "    criterion = TripletLoss()\n",
    "\n",
    "    val_prev = np.inf\n",
    "    \n",
    "    model.train()\n",
    "    for epoch in tqdm(range(epochs), desc=f\"Epochs {j}\"):\n",
    "        running_loss = []\n",
    "        for step, (anchor_claim, positive_claim, negative_claim, anchor_label) in enumerate(train_loader):\n",
    "            anchor_claim = anchor_claim.to(device)\n",
    "            positive_claim = positive_claim.to(device)\n",
    "            negative_claim = negative_claim.to(device)\n",
    "\n",
    "            optimizer.zero_grad()\n",
    "            anchor_out = model(anchor_claim)\n",
    "            positive_out = model(positive_claim)\n",
    "            negative_out = model(negative_claim)\n",
    "\n",
    "            loss = criterion(anchor_out, positive_out, negative_out)\n",
    "            loss.backward()\n",
    "            optimizer.step()\n",
    "\n",
    "            running_loss.append(loss.cpu().detach().numpy())\n",
    "\n",
    "        model.eval()\n",
    "    \n",
    "        val_loss = []\n",
    "        for anchor_claim, positive_claim, negative_claim, _ in val_loader:\n",
    "            anchor_claim = anchor_claim.to(device)\n",
    "            positive_claim = positive_claim.to(device)\n",
    "            negative_claim = negative_claim.to(device)\n",
    "\n",
    "            anchor_out = model(anchor_claim)\n",
    "            positive_out = model(positive_claim)\n",
    "            negative_out = model(negative_claim)\n",
    "\n",
    "            loss = criterion(anchor_out, positive_out, negative_out)\n",
    "            val_loss.append(loss.cpu().detach().numpy())\n",
    "\n",
    "        model.train()\n",
    "        \n",
    "        if np.mean(val_loss) < val_prev:\n",
    "            val_prev = np.mean(val_loss)\n",
    "            torch.save(model, f'model_cv{j}.pt')\n",
    "        \n",
    "        if epoch%100 == 0:\n",
    "            print(f\"{j} Epoch: {epoch+1}/{epochs} - Train Loss: {np.mean(running_loss):.4f};\",\n",
    "                  f\" Val Loss: {np.mean(val_loss):.4f} Val loss best {val_prev:.4f}\"\n",
    "             )\n",
    "            \n",
    "    \n",
    "    train_results = []\n",
    "    labels = []\n",
    "\n",
    "    model.eval()\n",
    "    with torch.no_grad():\n",
    "        for claim, _, _, label in train_loader:\n",
    "            anchor_claim = claim.to(device)\n",
    "\n",
    "            train_results.append(model(anchor_claim).cpu().numpy())\n",
    "            labels.append(label)\n",
    "\n",
    "\n",
    "    train_results = np.concatenate(train_results) \n",
    "    labels = np.concatenate(labels)\n",
    "\n",
    "    \n",
    "    test_results = []\n",
    "    test_labels = []\n",
    "\n",
    "    model.eval()\n",
    "    with torch.no_grad():\n",
    "        for claim, _, _, label in test_loader:\n",
    "            anchor_claim = claim.to(device)\n",
    "\n",
    "            test_results.append(model(anchor_claim).cpu().numpy())\n",
    "            test_labels.append(label)\n",
    "\n",
    "\n",
    "    test_results = np.concatenate(test_results)\n",
    "    test_labels = np.concatenate(test_labels)\n",
    "\n",
    "    \n",
    "    clf_lr_1 = LogisticRegression(max_iter=5000, C=1, penalty='l2', solver='liblinear')\n",
    "\n",
    "    y_train_t = labels\n",
    "    X_train_t = train_results\n",
    "    y_test_t = test_labels\n",
    "    X_test_t = test_results\n",
    "\n",
    "    clf_lr_1.fit(X_train_t, y_train_t)\n",
    "\n",
    "    y_pred = clf_lr_1.predict(X_test_t)\n",
    "\n",
    "    results['test_accuracy'].append( accuracy_score(y_test_t, y_pred) ) \n",
    "    results['test_precision'].append( precision_score(y_test_t, y_pred) ) \n",
    "    results['test_recall'].append( recall_score(y_test_t, y_pred) ) \n",
    "    results['test_f1'].append( f1_score(y_test_t, y_pred) ) \n",
    "\n",
    "\n",
    "out = {\n",
    "    \"Accuracy\": np.array(results['test_accuracy']),\n",
    "#     \"Precision\": np.array(results['test_precision']).mean(),\n",
    "#     \"Recall\": np.array(results['test_recall']).mean(),\n",
    "    \"F1 Score\":  np.array(results['test_f1']),\n",
    "    }\n",
    "\n",
    "print(\n",
    "    'triplet loss lr C1',\n",
    "    f'Accuracy {out[\"Accuracy\"].mean():.3f}+-{out[\"Accuracy\"].std():.3f}',\n",
    "    f'F1 Score {out[\"F1 Score\"].mean():.3f}+-{out[\"F1 Score\"].std():.3f}',\n",
    "    f' {out[\"Accuracy\"].mean():.3f}+-{out[\"Accuracy\"].std():.3f} | {out[\"F1 Score\"].mean():.3f}+-{out[\"F1 Score\"].std():.3f}'\n",
    ")    "
   ]
  },
  {
   "cell_type": "code",
   "execution_count": null,
   "metadata": {},
   "outputs": [],
   "source": []
  }
 ],
 "metadata": {
  "kernelspec": {
   "display_name": "Python 3 (ipykernel)",
   "language": "python",
   "name": "python3"
  },
  "language_info": {
   "codemirror_mode": {
    "name": "ipython",
    "version": 3
   },
   "file_extension": ".py",
   "mimetype": "text/x-python",
   "name": "python",
   "nbconvert_exporter": "python",
   "pygments_lexer": "ipython3",
   "version": "3.9.13"
  }
 },
 "nbformat": 4,
 "nbformat_minor": 4
}
